<?xml version="1.0"?> 
<sdf version="1.4">
	<model name="vilma_draw">
		<link name="chassis">
			<inertial>        
				<mass>1261.3</mass>
				<!--Used data from Punto weighing-->
				<inertia>
					<ixx>897.36767</ixx>
					<!-- Used model from "Mathematical Model for the Fiat punto, Olmer García, Mechanical Computational Department UNICAMP-->
					<ixy>0.0</ixy>
					<iyy>1825.0626</iyy>
					<ixz>0.0</ixz>
					<iyz>0.0</iyz>
					<izz>2722.4303</izz>
				</inertia>
				<!--OLD- chassis c.o.g. near lateral/longitudinal center, height of 0.4 m--> 
				<pose>0.358 0.0435 0.74625  0 0 0</pose>
				<!--Redefined so CG = calculated for X Y, and Z made total height/2 because not sure about value for cg height. -->
			</inertial>
			<visual name="visual">
				<!-- rotate mesh to get to X-forward 
        <pose>0 0 0 0 0 -1.570796</pose> -->
				<pose>-3.58 -2.465 -0.3 0 0 0</pose>
				<geometry>
					<mesh>
						<uri>model://vilma_draw/Fiatpuntosinruedas2.dae</uri>
						<scale>1 1 1</scale>
					</mesh>
				</geometry>       
			</visual>
			<collision name="chassis_collision">
				<pose>-3.58 -2.465 -0.3 0 0 0</pose>
				<geometry>
					<mesh>
						<uri>model://vilma_draw/Fiatpuntosinruedas2.dae</uri>
						<scale>1 1 1</scale>
					</mesh>
				</geometry> 
			</collision>      
		</link>
		<link name="rear_right_wheel">
			<!--pose>-0.85 -0.6 0.32  1.52 0.0 0.0</pose-->
			<pose>-1.2505 -0.735 0.32 1.52 0.0 0.0</pose>
			<inertial>
				<mass>12</mass>
				<!-- estimated from http://www.rzrforums.net/wheels-tires/1729-tire-wheel-weights-most-sizes.html -->
				<inertia>
					<ixx>0.160731</ixx>
					<!--Calculated using a cilinder model of the wheel, mass and 12kg and radius as 0.32m -->
					<ixy>0.0</ixy>
					<iyy>0.22815</iyy>
					<ixz>0.0</ixz>
					<iyz>0.0</iyz>
					<izz>0.160731</izz>
				</inertia>
			</inertial>
			<collision name="collision">
				<geometry>
					<cylinder>
						<radius>0.32</radius>
						<!--Actual radius = 0.3075 but mesh after a lot of effort ended up with around 3.2. -->
						<length>0.216</length>
					</cylinder>
				</geometry>
				<max_contacts>1</max_contacts>
				<surface>
					<friction>
						<ode>
							<mu>1.0</mu>
							<mu2>1.0</mu2>
							<fdir1>0 0 1</fdir1>
							<slip1>0.0</slip1>
							<slip2>0.0</slip2>
						</ode>
					</friction>
					<contact>
						<ode>
							<min_depth>0.005</min_depth>
							<kp>1e8</kp>
						</ode>
					</contact>
				</surface>
			</collision>
			<visual name="visual">
				<!-- rotate mesh to get to X-forward -->
				<pose>0 0 0 -1.570796 0 0</pose>
				<geometry>
					<mesh>
						<uri>model://vilma_draw/meshes/wheel.dae</uri>            
					</mesh>
				</geometry>
			</visual>
		</link>
		<link name="rear_left_wheel">
			<!--pose>-0.85 0.6 0.32  -1.52 0.0 0.0</pose-->
			<pose>-1.2505 0.735 0.32 -1.52 0.0 0.0</pose>
			<inertial>
				<mass>12</mass>
				<!-- estimated from http://www.rzrforums.net/wheels-tires/1729-tire-wheel-weights-most-sizes.html -->
				<inertia>
					<ixx>0.160731</ixx>
					<!--Calculated using a cilinder model of the wheel, mass and 12kg and radius as 0.32m -->
					<ixy>0.0</ixy>
					<iyy>0.22815</iyy>
					<ixz>0.0</ixz>
					<iyz>0.0</iyz>
					<izz>0.160731</izz>
				</inertia>
			</inertial>
			<collision name="collision">
				<geometry>
					<cylinder>
						<radius>0.32</radius>
						<!--Actual radius = 0.3075 but mesh after a lot of effort ended up with around 3.2. -->
						<length>0.216</length>
					</cylinder>
				</geometry>
				<max_contacts>1</max_contacts>
				<surface>
					<friction>
						<ode>
							<mu>1.0</mu>
							<mu2>1.0</mu2>
							<fdir1>0 0 1</fdir1>
							<slip1>0.0</slip1>
							<slip2>0.0</slip2>
						</ode>
					</friction>
					<contact>
						<ode>
							<min_depth>0.005</min_depth>
							<kp>1e8</kp>
						</ode>
					</contact>
				</surface>
			</collision>

			<visual name="visual">
				<!-- rotate mesh to get to X-forward -->
				<pose>0 0 0 -1.570796 0 0</pose>
				<geometry>
					<mesh>
						<uri>model://vilma_draw/meshes/wheel.dae</uri>            
					</mesh>
				</geometry>
			</visual>
		</link>

		<link name="front_right_wheel">
			<!--pose>1.03 -0.6 0.32 1.52 0.0 0.0</pose-->
			<pose>1.2505 -0.735 0.32 1.52 0.0 0.0</pose>
			<inertial>
				<mass>12</mass>
				<!-- estimated from http://www.rzrforums.net/wheels-tires/1729-tire-wheel-weights-most-sizes.html -->
				<inertia>
					<ixx>0.160731</ixx>
					<!--Calculated using a cilinder model of the wheel, mass and 12kg and radius as 0.32m -->
					<ixy>0.0</ixy>
					<iyy>0.22815</iyy>
					<ixz>0.0</ixz>
					<iyz>0.0</iyz>
					<izz>0.160731</izz>
				</inertia>
			</inertial>
			<collision name="collision">
				<geometry>
					<cylinder>
						<radius>0.32</radius>
						<!--Actual radius = 0.3075 but mesh after a lot of effort ended up with around 3.2. -->
						<length>0.216</length>
					</cylinder>
				</geometry>
				<max_contacts>1</max_contacts>
				<surface>
					<friction>
						<ode>
							<mu>1.0</mu>
							<mu2>1.0</mu2>
							<fdir1>0 0 1</fdir1>
							<slip1>0.0</slip1>
							<slip2>0.0</slip2>
						</ode>
					</friction>
					<contact>
						<ode>
							<min_depth>0.005</min_depth>
							<kp>1e8</kp>
						</ode>
					</contact>
				</surface>
			</collision>

			<visual name="visual">
				<!-- rotate mesh to get to X-forward -->
				<pose>0 0 0 -1.570796 0 0</pose>
				<geometry>
					<mesh>
						<uri>model://vilma_draw/meshes/wheel.dae</uri>            
					</mesh>
				</geometry>
			</visual>
		</link>

		<link name="front_right_wheel_steering_block">
			<pose>1.25 -0.635 0.32 1.570796 0.0 0.0</pose>
			<inertial>
				<mass>1</mass>
				<inertia>
					<ixx>1.0</ixx>
					<ixy>0.0</ixy>
					<iyy>1.0</iyy>
					<ixz>0.0</ixz>
					<iyz>0.0</iyz>
					<izz>1.0</izz>
				</inertia>
			</inertial>
			<collision name="collision">
				<geometry>
					<cylinder>
						<radius>0.05</radius>
						<length>0.01</length>
					</cylinder>
				</geometry>
			</collision>
		</link>
		<link name="front_left_wheel">
			<!--pose>1.03 0.6 0.32  -1.52 0.0 0.0</pose-->
			<pose>1.2505 0.735 0.32 -1.52 0.0 0.0</pose>
			<inertial>
				<mass>12</mass>
				<!-- estimated from http://www.rzrforums.net/wheels-tires/1729-tire-wheel-weights-most-sizes.html -->
				<inertia>
					<ixx>0.160731</ixx>
					<!--Calculated using a cilinder model of the wheel, mass and 12kg and radius as 0.32m -->
					<ixy>0.0</ixy>
					<iyy>0.22815</iyy>
					<ixz>0.0</ixz>
					<iyz>0.0</iyz>
					<izz>0.160731</izz>
				</inertia>
			</inertial>
			<collision name="collision">
				<geometry>
					<cylinder>
						<radius>0.32</radius>
						<!--Actual radius = 0.3075 but mesh after a lot of effort ended up with around 3.2. -->
						<length>0.216</length>
					</cylinder>
				</geometry>
				<max_contacts>1</max_contacts>
				<surface>
					<friction>
						<ode>
							<mu>1.0</mu>
							<mu2>1.0</mu2>
							<fdir1>0 0 1</fdir1>
							<slip1>0.0</slip1>
							<slip2>0.0</slip2>
						</ode>
					</friction>
					<contact>
						<ode>
							<min_depth>0.005</min_depth>
							<kp>1e8</kp>
						</ode>
					</contact>
				</surface>
			</collision>
			<visual name="visual">
				<!-- rotate mesh to get to X-forward -->
				<pose>0 0 0 -1.570796 0 0</pose>
				<geometry>
					<mesh>
						<uri>model://vilma_draw/meshes/wheel.dae</uri>            
					</mesh>
				</geometry>
			</visual>
		</link>
		<link name="front_left_wheel_steering_block">
			<pose>1.2505 0.635 0.32 1.570796 0.0 0.0</pose>
			<inertial>
				<mass>1</mass>
				<inertia>
					<ixx>1.0</ixx>
					<ixy>0.0</ixy>
					<iyy>1.0</iyy>
					<ixz>0.0</ixz>
					<iyz>0.0</iyz>
					<izz>1.0</izz>
				</inertia>
			</inertial>
			<collision name="collision">
				<geometry>
					<cylinder>
						<radius>0.05</radius>
						<length>0.01</length>
					</cylinder>
				</geometry>
			</collision>
		</link>
		<!-- gas/brake pedals, steering wheel and hand brake -->
		<link name='gas_pedal'>
			<pose>0.63 0.10 2.0 0 0 0</pose>
			<gravity>false</gravity>
			<inertial>
				<mass>0.1</mass>
				<pose>0 0 0 0 0 0</pose>
				<inertia>
					<ixx>0.01</ixx>
					<ixy>0</ixy>
					<ixz>0</ixz>
					<iyy>0.01</iyy>
					<iyz>0</iyz>
					<izz>0.01</izz>
				</inertia>
			</inertial>
			<collision name='gas_pedal_collision'>
				<pose>-0.0385 0 -0.086 0 2.016 0</pose>
				<geometry>
					<box>
						<size>0.1069000 0.0770000 0.010000</size>
					</box>
				</geometry>
			</collision>
			<visual name="visual">
				<!-- rotate mesh to get to X-forward -->
				<pose>0 0 0 0 0 -1.5707</pose>
				<geometry>
					<mesh>
						<uri>model://vilma_draw/meshes/polaris.dae</uri>
						<submesh>
							<name>Pedal_Gas</name>
							<center>true</center>
						</submesh>
					</mesh>
				</geometry>
			</visual>
		</link>

		<link name='brake_pedal'>
			<gravity>false</gravity>
			<pose>0.64 0.27 2.0 0 0 0</pose>
			<inertial>
				<mass>0.1</mass>
				<pose>0 0 0 0 0 0</pose>
				<inertia>
					<ixx>0.01</ixx>
					<ixy>0</ixy>
					<ixz>0</ixz>
					<iyy>0.01</iyy>
					<iyz>0</iyz>
					<izz>0.01</izz>
				</inertia>
			</inertial>
			<collision name='brake_pedal_collision'>
				<pose>-0.040 0 -0.086 0 1.999 0</pose>
				<geometry>
					<box>
						<size>0.063 0.08 0.01</size>
					</box>
				</geometry>
			</collision>
			<visual name="visual">
				<!-- rotate mesh to get to X-forward -->
				<pose>0 0 0 0 0 -1.5707</pose>
				<geometry>
					<mesh>
						<uri>model://vilma_draw/meshes/polaris.dae</uri>
						<submesh>
							<name>Pedal_brake</name>
							<center>true</center>
						</submesh>
					</mesh>
				</geometry>
			</visual>
		</link>

		<link name='steering_wheel'>
			<pose>0.34 0.30 2.0  0 -0.87 0</pose> 
			<inertial>
				<mass>1.0</mass>
				<pose>-0.002 0 0  0 0 0</pose>
				<inertia>
					<ixx>0.012</ixx>
					<ixy>0</ixy>
					<ixz>0</ixz>
					<iyy>0.012</iyy>
					<iyz>0</iyz>
					<izz>0.024</izz>
				</inertia>
			</inertial>

			<collision name="collision">
				<!-- rotate mesh to get to X-forward -->
				<pose>0 0 0  -0.69 0 -1.570796</pose>
				<geometry>
					<mesh>
						<uri>model://vilma_draw/meshes/polaris.dae</uri>
						<submesh>
							<name>Steering_Wheel</name>
							<center>true</center>
						</submesh>
					</mesh>
				</geometry>
				<surface>
					<contact>
						<ode>
							<min_depth>0.003</min_depth>
						</ode>
					</contact>
				</surface>
			</collision>

			<visual name="visual">
				<!-- rotate mesh to get to X-forward -->
				<pose>0 0 0  -0.69 0 -1.570796</pose>
				<geometry>
					<mesh>
						<uri>model://vilma_draw/meshes/polaris.dae</uri>
						<submesh>
							<name>Steering_Wheel</name>
							<center>true</center>
						</submesh>
					</mesh>
				</geometry>
			</visual>
			<!-- visual used to measure size of mesh steering wheel -->
			<!--visual name="vis_cyl">
        <pose>0 0 0  0 0 0</pose>
        <geometry>
          <cylinder>
            <radius>0.16</radius>
            <length>0.01</length>
          </cylinder>
        </geometry>
      </visual-->
		</link>

		<link name='hand_brake'>
			<pose>0.50 0.00 1.05 0.0 3.2 0.0</pose>
			<!--pose>0.53 0.07 1.5  0 0 0</pose-->
			<inertial>
				<mass>0.5</mass>
				<inertia>
					<ixx>0.1</ixx>
					<ixy>0</ixy>
					<ixz>0</ixz>
					<iyy>0.1</iyy>
					<iyz>0</iyz>
					<izz>0.05</izz>
				</inertia>
			</inertial>
			<collision name="hand_brake_collision">
				<pose>0 0 -0.10 0 0 0</pose>
				<geometry>
					<cylinder>
						<radius>0.01</radius>
						<length>0.2</length>
					</cylinder>
				</geometry>
			</collision>
			<visual name="hand_brake_visual">
				<pose>0 0 -0.10 0 0 0</pose>
				<geometry>
					<cylinder>
						<radius>0.01</radius>
						<length>0.2</length>
					</cylinder>
				</geometry>
				<material>
					<script>
						<uri>file://media/materials/scripts/gazebo.material</uri>
						<name>Gazebo/Wood</name>
					</script>
				</material>
			</visual>
		</link>

		<link name='FNR_switch'>
			<pose>0.56 -0.02 2.0  0 0.25 0</pose> 
			<inertial>
				<mass>0.1</mass>
				<inertia>
					<!-- constrained about x axis -->
					<!--ixx>0.00002</ixx-->
					<ixx>0.1</ixx>
					<ixy>0</ixy>
					<ixz>0</ixz>
					<iyy>0.00006</iyy>
					<iyz>0</iyz>
					<!-- constrained about z axis -->
					<!--izz>0.00007</izz-->
					<izz>0.1</izz>
				</inertia>
			</inertial>
			<collision name="FNR_switch">
				<geometry>
					<box>
						<size>0.02 0.04 0.08</size>
					</box>
				</geometry>
			</collision>
			<visual name="FNR_switch_F">
				<transparency>0.0</transparency>
				<geometry>
					<box>
						<size>0.02 0.04 0.08</size>
					</box>
				</geometry>
				<material>
					<script>
						<uri>model://vilma_draw/materials/scripts</uri>
						<uri>model://vilma_draw/materials/textures</uri>
						<name>FNR_switch_F</name>
					</script>
				</material>
			</visual>
			<visual name="FNR_switch_R">
				<transparency>1.0</transparency>
				<geometry>
					<box>
						<size>0.0199 0.0399 0.0799</size>
					</box>
				</geometry>
				<material>
					<script>
						<uri>model://vilma_draw/materials/scripts</uri>
						<uri>model://vilma_draw/materials/textures</uri>
						<name>FNR_switch_R</name>
					</script>
				</material>
			</visual>
		</link>

		<joint type="revolute" name="front_left_steering_joint">
			<child>front_left_wheel_steering_block</child>
			<parent>chassis</parent>
			<axis>
				<xyz>0 0 1</xyz>
				<limit>
					<!-- +- 50 degrees -->
					<lower>-0.8727</lower>
					<upper>0.8727</upper>
				</limit>
				<dynamics>
					<damping>50.0</damping>
				</dynamics>
			</axis>
			<physics>
				<ode>
					<cfm_damping>1</cfm_damping>
					<limit>
						<cfm>0.000000</cfm>
						<erp>0.900000</erp>
					</limit>
				</ode>
			</physics>
		</joint>
		<joint type="revolute" name="front_left_wheel_joint">
			<child>front_left_wheel</child>
			<parent>front_left_wheel_steering_block</parent>
			<axis>
				<xyz>0 1 0.05</xyz>
			</axis>
		</joint>

		<joint type="revolute" name="front_right_steering_joint">
			<child>front_right_wheel_steering_block</child>
			<parent>chassis</parent>
			<axis>
				<xyz>0 0 1</xyz>
				<limit>
					<!-- +- 50 degrees -->
					<lower>-0.8727</lower>
					<upper>0.8727</upper>
				</limit>
				<dynamics>
					<damping>50.0</damping>
				</dynamics>
			</axis>
			<physics>
				<ode>
					<cfm_damping>1</cfm_damping>
					<limit>
						<cfm>0.000000</cfm>
						<erp>0.900000</erp>
					</limit>
				</ode>
			</physics>
		</joint>

		<joint type="revolute" name="front_right_wheel_joint">
			<child>front_right_wheel</child>
			<parent>front_right_wheel_steering_block</parent>
			<axis>
				<xyz>0 1 -0.05</xyz>
			</axis>
		</joint>


		<joint type="revolute" name="rear_left_wheel_joint">
			<child>rear_left_wheel</child>
			<parent>chassis</parent>
			<axis>
				<xyz>0 1 0.05</xyz>
			</axis>
		</joint>

		<joint type="revolute" name="rear_right_wheel_joint">
			<pose>0.0 0.0 -0.1 0 0 0</pose>
			<child>rear_right_wheel</child>
			<parent>chassis</parent>
			<axis>
				<xyz>0 1 -0.05</xyz>
			</axis>
		</joint>

		<joint type="revolute" name="rear_differential_joint">
			<child>rear_right_wheel</child>
			<parent>rear_left_wheel</parent>
			<axis>
				<!-- expressed in chassis frame -->
				<xyz>0 1 0</xyz>
				<dynamics>
					<damping>70</damping>
				</dynamics>
			</axis>
			<physics>
				<ode>
					<erp>0</erp>
					<cfm>1000</cfm>
					<cfm_damping>1</cfm_damping>
				</ode>
			</physics>
		</joint>

		<joint name='gas_joint' type='prismatic'>
			<parent>chassis</parent>
			<child>gas_pedal</child>
			<axis>
				<xyz>1.000000 0.000000 -1.000000</xyz>
				<limit>
					<lower>0.00</lower>
					<upper>0.08</upper>
				</limit>
				<dynamics>
					<damping>3.0</damping>
				</dynamics>
			</axis>
			<physics>
				<ode>
					<cfm_damping>1</cfm_damping>
				</ode>
			</physics>
		</joint>
		<joint name='brake_joint' type='prismatic'>
			<parent>chassis</parent>
			<child>brake_pedal</child>
			<axis>
				<xyz>1.000000 0.000000 -0.600000</xyz>
				<limit>
					<lower>0.00</lower>
					<upper>0.08</upper>
				</limit>
				<dynamics>
					<damping>3.0</damping>
				</dynamics>
			</axis>
			<physics>
				<ode>
					<cfm_damping>1</cfm_damping>
				</ode>
			</physics>
		</joint>
		<joint name='steering_joint' type='revolute'>
			<pose>-0.002 0 0  0 0 0</pose>
			<parent>chassis</parent>
			<child>steering_wheel</child>
			<axis>
				<xyz>-1 0 0.84365</xyz>
				<limit>
					<lower>-3.14</lower>
					<upper>3.14</upper>
				</limit>
				<dynamics>
					<damping>1.0</damping>
				</dynamics>
			</axis>
			<physics>
				<ode>
					<cfm_damping>1</cfm_damping>
				</ode>
			</physics>
		</joint>
		<joint name='hand_brake_joint' type='revolute'>
			<parent>chassis</parent>
			<child>hand_brake</child>
			<axis>
				<xyz>0.0 -1.0 0.0</xyz>
				<limit>
					<lower>0</lower>
					<upper>0.6</upper>
				</limit>
				<dynamics>
					<damping>1.0</damping>
				</dynamics>
			</axis>
			<physics>
				<ode>
					<cfm_damping>1</cfm_damping>
				</ode>
			</physics>
		</joint>
		<joint name='FNR_switch_joint' type='revolute'>
			<parent>chassis</parent>
			<child>FNR_switch</child>
			<axis>
				<xyz>0.0 -1.0 0.0</xyz>
				<limit>
					<lower>-0.3</lower>
					<upper>0.3</upper>
				</limit>
				<dynamics>
					<damping>0.01</damping>
				</dynamics>
			</axis>
			<physics>
				<ode>
					<cfm_damping>1</cfm_damping>
				</ode>
			</physics>
		</joint>

	</model>
</sdf>
