<sdf version='1.4'>
  <world name='vilma_task_1'>
    <gui fullscreen='0'>
      <camera name='user_camera'>
        <pose>133.713 -41.0036 49.596 0 0.375644 1.96418</pose>
        <view_controller>orbit</view_controller>
      </camera>
    </gui>
    <scene>
      <ambient>0.2 0.2 0.2 1</ambient>
      <grid>0</grid>
      <background>0.7 0.7 0.7 1</background>
      <shadows>1</shadows>
    </scene>
    <physics type='ode'>
      <gravity>0 0 -9.81</gravity>
      <ode>
        <solver>
          <type>quick</type>
          <iters>50</iters>
          <sor>1.4</sor>
        </solver>
        <constraints>
          <cfm>0</cfm>
          <erp>0.2</erp>
          <contact_max_correcting_vel>100</contact_max_correcting_vel>
          <contact_surface_layer>0</contact_surface_layer>
        </constraints>
      </ode>
      <real_time_update_rate>1000</real_time_update_rate>
      <max_step_size>0.001</max_step_size>
      <real_time_factor>1</real_time_factor>
    </physics>
    <light name='sun' type='directional'>
      <cast_shadows>0</cast_shadows>
      <pose>0 0 100 0 -0 0</pose>
      <diffuse>0.8 0.8 0.8 1</diffuse>
      <specular>0.9 0.9 0.9 1</specular>
      <attenuation>
        <range>1000</range>
        <constant>0.9</constant>
        <linear>0.01</linear>
        <quadratic>0.001</quadratic>
      </attenuation>
      <direction>0.2 0.2 -0.9</direction>
    </light>
    <model name='grass_plane'>
      <static>1</static>
      <link name='link'>
        <collision name='collision'>
          <geometry>
            <plane>
              <normal>0 0 1</normal>
              <size>500 500</size>
            </plane>
          </geometry>
          <surface>
            <friction>
              <ode>
                <mu>0.5</mu>
                <mu2>0.5</mu2>
              </ode>
            </friction>
            <bounce/>
            <contact>
              <ode/>
            </contact>
          </surface>
          <max_contacts>10</max_contacts>
        </collision>
        <visual name='visual_0'>
          <pose>-40 -40 0 0 -0 0</pose>
          <cast_shadows>0</cast_shadows>
          <geometry>
            <plane>
              <normal>0 0 1</normal>
              <size>20 20</size>
            </plane>
          </geometry>
          <material>
            <script>
              <uri>model://grass_plane/materials/scripts</uri>
              <uri>model://grass_plane/materials/textures</uri>
              <name>vrc/grass</name>
            </script>
          </material>
        </visual>
        <visual name='visual_1'>
          <pose>-20 -40 0 0 -0 0</pose>
          <cast_shadows>0</cast_shadows>
          <geometry>
            <plane>
              <normal>0 0 1</normal>
              <size>20 20</size>
            </plane>
          </geometry>
          <material>
            <script>
              <uri>model://grass_plane/materials/scripts</uri>
              <uri>model://grass_plane/materials/textures</uri>
              <name>vrc/grass</name>
            </script>
          </material>
        </visual>
        <visual name='visual_2'>
          <pose>0 -40 0 0 -0 0</pose>
          <cast_shadows>0</cast_shadows>
          <geometry>
            <plane>
              <normal>0 0 1</normal>
              <size>20 20</size>
            </plane>
          </geometry>
          <material>
            <script>
              <uri>model://grass_plane/materials/scripts</uri>
              <uri>model://grass_plane/materials/textures</uri>
              <name>vrc/grass</name>
            </script>
          </material>
        </visual>
        <visual name='visual_3'>
          <pose>20 -40 0 0 -0 0</pose>
          <cast_shadows>0</cast_shadows>
          <geometry>
            <plane>
              <normal>0 0 1</normal>
              <size>20 20</size>
            </plane>
          </geometry>
          <material>
            <script>
              <uri>model://grass_plane/materials/scripts</uri>
              <uri>model://grass_plane/materials/textures</uri>
              <name>vrc/grass</name>
            </script>
          </material>
        </visual>
        <visual name='visual_4'>
          <pose>40 -40 0 0 -0 0</pose>
          <cast_shadows>0</cast_shadows>
          <geometry>
            <plane>
              <normal>0 0 1</normal>
              <size>20 20</size>
            </plane>
          </geometry>
          <material>
            <script>
              <uri>model://grass_plane/materials/scripts</uri>
              <uri>model://grass_plane/materials/textures</uri>
              <name>vrc/grass</name>
            </script>
          </material>
        </visual>
        <visual name='visual_5'>
          <pose>60 -40 0 0 -0 0</pose>
          <cast_shadows>0</cast_shadows>
          <geometry>
            <plane>
              <normal>0 0 1</normal>
              <size>20 20</size>
            </plane>
          </geometry>
          <material>
            <script>
              <uri>model://grass_plane/materials/scripts</uri>
              <uri>model://grass_plane/materials/textures</uri>
              <name>vrc/grass</name>
            </script>
          </material>
        </visual>
        <visual name='visual_6'>
          <pose>-40 -20 0 0 -0 0</pose>
          <cast_shadows>0</cast_shadows>
          <geometry>
            <plane>
              <normal>0 0 1</normal>
              <size>20 20</size>
            </plane>
          </geometry>
          <material>
            <script>
              <uri>model://grass_plane/materials/scripts</uri>
              <uri>model://grass_plane/materials/textures</uri>
              <name>vrc/grass</name>
            </script>
          </material>
        </visual>
        <visual name='visual_7'>
          <pose>-20 -20 0 0 -0 0</pose>
          <cast_shadows>0</cast_shadows>
          <geometry>
            <plane>
              <normal>0 0 1</normal>
              <size>20 20</size>
            </plane>
          </geometry>
          <material>
            <script>
              <uri>model://grass_plane/materials/scripts</uri>
              <uri>model://grass_plane/materials/textures</uri>
              <name>vrc/grass</name>
            </script>
          </material>
        </visual>
        <visual name='visual_8'>
          <pose>0 -20 0 0 -0 0</pose>
          <cast_shadows>0</cast_shadows>
          <geometry>
            <plane>
              <normal>0 0 1</normal>
              <size>20 20</size>
            </plane>
          </geometry>
          <material>
            <script>
              <uri>model://grass_plane/materials/scripts</uri>
              <uri>model://grass_plane/materials/textures</uri>
              <name>vrc/grass</name>
            </script>
          </material>
        </visual>
        <visual name='visual_9'>
          <pose>20 -20 0 0 -0 0</pose>
          <cast_shadows>0</cast_shadows>
          <geometry>
            <plane>
              <normal>0 0 1</normal>
              <size>20 20</size>
            </plane>
          </geometry>
          <material>
            <script>
              <uri>model://grass_plane/materials/scripts</uri>
              <uri>model://grass_plane/materials/textures</uri>
              <name>vrc/grass</name>
            </script>
          </material>
        </visual>
        <visual name='visual_10'>
          <pose>40 -20 0 0 -0 0</pose>
          <cast_shadows>0</cast_shadows>
          <geometry>
            <plane>
              <normal>0 0 1</normal>
              <size>20 20</size>
            </plane>
          </geometry>
          <material>
            <script>
              <uri>model://grass_plane/materials/scripts</uri>
              <uri>model://grass_plane/materials/textures</uri>
              <name>vrc/grass</name>
            </script>
          </material>
        </visual>
        <visual name='visual_11'>
          <pose>60 -20 0 0 -0 0</pose>
          <cast_shadows>0</cast_shadows>
          <geometry>
            <plane>
              <normal>0 0 1</normal>
              <size>20 20</size>
            </plane>
          </geometry>
          <material>
            <script>
              <uri>model://grass_plane/materials/scripts</uri>
              <uri>model://grass_plane/materials/textures</uri>
              <name>vrc/grass</name>
            </script>
          </material>
        </visual>
        <visual name='visual_12'>
          <pose>80 -20 0 0 -0 0</pose>
          <cast_shadows>0</cast_shadows>
          <geometry>
            <plane>
              <normal>0 0 1</normal>
              <size>20 20</size>
            </plane>
          </geometry>
          <material>
            <script>
              <uri>model://grass_plane/materials/scripts</uri>
              <uri>model://grass_plane/materials/textures</uri>
              <name>vrc/grass</name>
            </script>
          </material>
        </visual>
        <visual name='visual_13'>
          <pose>-40 0 0 0 -0 0</pose>
          <cast_shadows>0</cast_shadows>
          <geometry>
            <plane>
              <normal>0 0 1</normal>
              <size>20 20</size>
            </plane>
          </geometry>
          <material>
            <script>
              <uri>model://grass_plane/materials/scripts</uri>
              <uri>model://grass_plane/materials/textures</uri>
              <name>vrc/grass</name>
            </script>
          </material>
        </visual>
        <visual name='visual_14'>
          <pose>-20 0 0 0 -0 0</pose>
          <cast_shadows>0</cast_shadows>
          <geometry>
            <plane>
              <normal>0 0 1</normal>
              <size>20 20</size>
            </plane>
          </geometry>
          <material>
            <script>
              <uri>model://grass_plane/materials/scripts</uri>
              <uri>model://grass_plane/materials/textures</uri>
              <name>vrc/grass</name>
            </script>
          </material>
        </visual>
        <visual name='visual_15'>
          <pose>0 0 0 0 -0 0</pose>
          <cast_shadows>0</cast_shadows>
          <geometry>
            <plane>
              <normal>0 0 1</normal>
              <size>20 20</size>
            </plane>
          </geometry>
          <material>
            <script>
              <uri>model://grass_plane/materials/scripts</uri>
              <uri>model://grass_plane/materials/textures</uri>
              <name>vrc/grass</name>
            </script>
          </material>
        </visual>
        <visual name='visual_16'>
          <pose>20 0 0 0 -0 0</pose>
          <cast_shadows>0</cast_shadows>
          <geometry>
            <plane>
              <normal>0 0 1</normal>
              <size>20 20</size>
            </plane>
          </geometry>
          <material>
            <script>
              <uri>model://grass_plane/materials/scripts</uri>
              <uri>model://grass_plane/materials/textures</uri>
              <name>vrc/grass</name>
            </script>
          </material>
        </visual>
        <visual name='visual_17'>
          <pose>40 0 0 0 -0 0</pose>
          <cast_shadows>0</cast_shadows>
          <geometry>
            <plane>
              <normal>0 0 1</normal>
              <size>20 20</size>
            </plane>
          </geometry>
          <material>
            <script>
              <uri>model://grass_plane/materials/scripts</uri>
              <uri>model://grass_plane/materials/textures</uri>
              <name>vrc/grass</name>
            </script>
          </material>
        </visual>
        <visual name='visual_18'>
          <pose>60 0 0 0 -0 0</pose>
          <cast_shadows>0</cast_shadows>
          <geometry>
            <plane>
              <normal>0 0 1</normal>
              <size>20 20</size>
            </plane>
          </geometry>
          <material>
            <script>
              <uri>model://grass_plane/materials/scripts</uri>
              <uri>model://grass_plane/materials/textures</uri>
              <name>vrc/grass</name>
            </script>
          </material>
        </visual>
        <visual name='visual_19'>
          <pose>80 0 0 0 -0 0</pose>
          <cast_shadows>0</cast_shadows>
          <geometry>
            <plane>
              <normal>0 0 1</normal>
              <size>20 20</size>
            </plane>
          </geometry>
          <material>
            <script>
              <uri>model://grass_plane/materials/scripts</uri>
              <uri>model://grass_plane/materials/textures</uri>
              <name>vrc/grass</name>
            </script>
          </material>
        </visual>
        <visual name='visual_20'>
          <pose>100 0 0 0 -0 0</pose>
          <cast_shadows>0</cast_shadows>
          <geometry>
            <plane>
              <normal>0 0 1</normal>
              <size>20 20</size>
            </plane>
          </geometry>
          <material>
            <script>
              <uri>model://grass_plane/materials/scripts</uri>
              <uri>model://grass_plane/materials/textures</uri>
              <name>vrc/grass</name>
            </script>
          </material>
        </visual>
        <visual name='visual_21'>
          <pose>120 0 0 0 -0 0</pose>
          <cast_shadows>0</cast_shadows>
          <geometry>
            <plane>
              <normal>0 0 1</normal>
              <size>20 20</size>
            </plane>
          </geometry>
          <material>
            <script>
              <uri>model://grass_plane/materials/scripts</uri>
              <uri>model://grass_plane/materials/textures</uri>
              <name>vrc/grass</name>
            </script>
          </material>
        </visual>
        <visual name='visual_22'>
          <pose>-40 20 0 0 -0 0</pose>
          <cast_shadows>0</cast_shadows>
          <geometry>
            <plane>
              <normal>0 0 1</normal>
              <size>20 20</size>
            </plane>
          </geometry>
          <material>
            <script>
              <uri>model://grass_plane/materials/scripts</uri>
              <uri>model://grass_plane/materials/textures</uri>
              <name>vrc/grass</name>
            </script>
          </material>
        </visual>
        <visual name='visual_23'>
          <pose>-20 20 0 0 -0 0</pose>
          <cast_shadows>0</cast_shadows>
          <geometry>
            <plane>
              <normal>0 0 1</normal>
              <size>20 20</size>
            </plane>
          </geometry>
          <material>
            <script>
              <uri>model://grass_plane/materials/scripts</uri>
              <uri>model://grass_plane/materials/textures</uri>
              <name>vrc/grass</name>
            </script>
          </material>
        </visual>
        <visual name='visual_24'>
          <pose>0 20 0 0 -0 0</pose>
          <cast_shadows>0</cast_shadows>
          <geometry>
            <plane>
              <normal>0 0 1</normal>
              <size>20 20</size>
            </plane>
          </geometry>
          <material>
            <script>
              <uri>model://grass_plane/materials/scripts</uri>
              <uri>model://grass_plane/materials/textures</uri>
              <name>vrc/grass</name>
            </script>
          </material>
        </visual>
        <visual name='visual_25'>
          <pose>20 20 0 0 -0 0</pose>
          <cast_shadows>0</cast_shadows>
          <geometry>
            <plane>
              <normal>0 0 1</normal>
              <size>20 20</size>
            </plane>
          </geometry>
          <material>
            <script>
              <uri>model://grass_plane/materials/scripts</uri>
              <uri>model://grass_plane/materials/textures</uri>
              <name>vrc/grass</name>
            </script>
          </material>
        </visual>
        <visual name='visual_26'>
          <pose>40 20 0 0 -0 0</pose>
          <cast_shadows>0</cast_shadows>
          <geometry>
            <plane>
              <normal>0 0 1</normal>
              <size>20 20</size>
            </plane>
          </geometry>
          <material>
            <script>
              <uri>model://grass_plane/materials/scripts</uri>
              <uri>model://grass_plane/materials/textures</uri>
              <name>vrc/grass</name>
            </script>
          </material>
        </visual>
        <visual name='visual_27'>
          <pose>60 20 0 0 -0 0</pose>
          <cast_shadows>0</cast_shadows>
          <geometry>
            <plane>
              <normal>0 0 1</normal>
              <size>20 20</size>
            </plane>
          </geometry>
          <material>
            <script>
              <uri>model://grass_plane/materials/scripts</uri>
              <uri>model://grass_plane/materials/textures</uri>
              <name>vrc/grass</name>
            </script>
          </material>
        </visual>
        <visual name='visual_28'>
          <pose>80 20 0 0 -0 0</pose>
          <cast_shadows>0</cast_shadows>
          <geometry>
            <plane>
              <normal>0 0 1</normal>
              <size>20 20</size>
            </plane>
          </geometry>
          <material>
            <script>
              <uri>model://grass_plane/materials/scripts</uri>
              <uri>model://grass_plane/materials/textures</uri>
              <name>vrc/grass</name>
            </script>
          </material>
        </visual>
        <visual name='visual_29'>
          <pose>100 20 0 0 -0 0</pose>
          <cast_shadows>0</cast_shadows>
          <geometry>
            <plane>
              <normal>0 0 1</normal>
              <size>20 20</size>
            </plane>
          </geometry>
          <material>
            <script>
              <uri>model://grass_plane/materials/scripts</uri>
              <uri>model://grass_plane/materials/textures</uri>
              <name>vrc/grass</name>
            </script>
          </material>
        </visual>
        <visual name='visual_30'>
          <pose>120 20 0 0 -0 0</pose>
          <cast_shadows>0</cast_shadows>
          <geometry>
            <plane>
              <normal>0 0 1</normal>
              <size>20 20</size>
            </plane>
          </geometry>
          <material>
            <script>
              <uri>model://grass_plane/materials/scripts</uri>
              <uri>model://grass_plane/materials/textures</uri>
              <name>vrc/grass</name>
            </script>
          </material>
        </visual>
        <visual name='visual_31'>
          <pose>140 20 0 0 -0 0</pose>
          <cast_shadows>0</cast_shadows>
          <geometry>
            <plane>
              <normal>0 0 1</normal>
              <size>20 20</size>
            </plane>
          </geometry>
          <material>
            <script>
              <uri>model://grass_plane/materials/scripts</uri>
              <uri>model://grass_plane/materials/textures</uri>
              <name>vrc/grass</name>
            </script>
          </material>
        </visual>
        <visual name='visual_32'>
          <pose>40 40 0 0 -0 0</pose>
          <cast_shadows>0</cast_shadows>
          <geometry>
            <plane>
              <normal>0 0 1</normal>
              <size>20 20</size>
            </plane>
          </geometry>
          <material>
            <script>
              <uri>model://grass_plane/materials/scripts</uri>
              <uri>model://grass_plane/materials/textures</uri>
              <name>vrc/grass</name>
            </script>
          </material>
        </visual>
        <visual name='visual_33'>
          <pose>60 40 0 0 -0 0</pose>
          <cast_shadows>0</cast_shadows>
          <geometry>
            <plane>
              <normal>0 0 1</normal>
              <size>20 20</size>
            </plane>
          </geometry>
          <material>
            <script>
              <uri>model://grass_plane/materials/scripts</uri>
              <uri>model://grass_plane/materials/textures</uri>
              <name>vrc/grass</name>
            </script>
          </material>
        </visual>
        <visual name='visual_34'>
          <pose>80 40 0 0 -0 0</pose>
          <cast_shadows>0</cast_shadows>
          <geometry>
            <plane>
              <normal>0 0 1</normal>
              <size>20 20</size>
            </plane>
          </geometry>
          <material>
            <script>
              <uri>model://grass_plane/materials/scripts</uri>
              <uri>model://grass_plane/materials/textures</uri>
              <name>vrc/grass</name>
            </script>
          </material>
        </visual>
        <visual name='visual_35'>
          <pose>100 40 0 0 -0 0</pose>
          <cast_shadows>0</cast_shadows>
          <geometry>
            <plane>
              <normal>0 0 1</normal>
              <size>20 20</size>
            </plane>
          </geometry>
          <material>
            <script>
              <uri>model://grass_plane/materials/scripts</uri>
              <uri>model://grass_plane/materials/textures</uri>
              <name>vrc/grass</name>
            </script>
          </material>
        </visual>
        <visual name='visual_36'>
          <pose>120 40 0 0 -0 0</pose>
          <cast_shadows>0</cast_shadows>
          <geometry>
            <plane>
              <normal>0 0 1</normal>
              <size>20 20</size>
            </plane>
          </geometry>
          <material>
            <script>
              <uri>model://grass_plane/materials/scripts</uri>
              <uri>model://grass_plane/materials/textures</uri>
              <name>vrc/grass</name>
            </script>
          </material>
        </visual>
        <visual name='visual_37'>
          <pose>140 40 0 0 -0 0</pose>
          <cast_shadows>0</cast_shadows>
          <geometry>
            <plane>
              <normal>0 0 1</normal>
              <size>20 20</size>
            </plane>
          </geometry>
          <material>
            <script>
              <uri>model://grass_plane/materials/scripts</uri>
              <uri>model://grass_plane/materials/textures</uri>
              <name>vrc/grass</name>
            </script>
          </material>
        </visual>
        <visual name='visual_38'>
          <pose>160 40 0 0 -0 0</pose>
          <cast_shadows>0</cast_shadows>
          <geometry>
            <plane>
              <normal>0 0 1</normal>
              <size>20 20</size>
            </plane>
          </geometry>
          <material>
            <script>
              <uri>model://grass_plane/materials/scripts</uri>
              <uri>model://grass_plane/materials/textures</uri>
              <name>vrc/grass</name>
            </script>
          </material>
        </visual>
        <visual name='visual_39'>
          <pose>40 60 0 0 -0 0</pose>
          <cast_shadows>0</cast_shadows>
          <geometry>
            <plane>
              <normal>0 0 1</normal>
              <size>20 20</size>
            </plane>
          </geometry>
          <material>
            <script>
              <uri>model://grass_plane/materials/scripts</uri>
              <uri>model://grass_plane/materials/textures</uri>
              <name>vrc/grass</name>
            </script>
          </material>
        </visual>
        <visual name='visual_40'>
          <pose>60 60 0 0 -0 0</pose>
          <cast_shadows>0</cast_shadows>
          <geometry>
            <plane>
              <normal>0 0 1</normal>
              <size>20 20</size>
            </plane>
          </geometry>
          <material>
            <script>
              <uri>model://grass_plane/materials/scripts</uri>
              <uri>model://grass_plane/materials/textures</uri>
              <name>vrc/grass</name>
            </script>
          </material>
        </visual>
        <visual name='visual_41'>
          <pose>80 60 0 0 -0 0</pose>
          <cast_shadows>0</cast_shadows>
          <geometry>
            <plane>
              <normal>0 0 1</normal>
              <size>20 20</size>
            </plane>
          </geometry>
          <material>
            <script>
              <uri>model://grass_plane/materials/scripts</uri>
              <uri>model://grass_plane/materials/textures</uri>
              <name>vrc/grass</name>
            </script>
          </material>
        </visual>
        <visual name='visual_42'>
          <pose>100 60 0 0 -0 0</pose>
          <cast_shadows>0</cast_shadows>
          <geometry>
            <plane>
              <normal>0 0 1</normal>
              <size>20 20</size>
            </plane>
          </geometry>
          <material>
            <script>
              <uri>model://grass_plane/materials/scripts</uri>
              <uri>model://grass_plane/materials/textures</uri>
              <name>vrc/grass</name>
            </script>
          </material>
        </visual>
        <visual name='visual_43'>
          <pose>120 60 0 0 -0 0</pose>
          <cast_shadows>0</cast_shadows>
          <geometry>
            <plane>
              <normal>0 0 1</normal>
              <size>20 20</size>
            </plane>
          </geometry>
          <material>
            <script>
              <uri>model://grass_plane/materials/scripts</uri>
              <uri>model://grass_plane/materials/textures</uri>
              <name>vrc/grass</name>
            </script>
          </material>
        </visual>
        <visual name='visual_44'>
          <pose>140 60 0 0 -0 0</pose>
          <cast_shadows>0</cast_shadows>
          <geometry>
            <plane>
              <normal>0 0 1</normal>
              <size>20 20</size>
            </plane>
          </geometry>
          <material>
            <script>
              <uri>model://grass_plane/materials/scripts</uri>
              <uri>model://grass_plane/materials/textures</uri>
              <name>vrc/grass</name>
            </script>
          </material>
        </visual>
        <visual name='visual_45'>
          <pose>160 60 0 0 -0 0</pose>
          <cast_shadows>0</cast_shadows>
          <geometry>
            <plane>
              <normal>0 0 1</normal>
              <size>20 20</size>
            </plane>
          </geometry>
          <material>
            <script>
              <uri>model://grass_plane/materials/scripts</uri>
              <uri>model://grass_plane/materials/textures</uri>
              <name>vrc/grass</name>
            </script>
          </material>
        </visual>
        <visual name='visual_46'>
          <pose>40 80 0 0 -0 0</pose>
          <cast_shadows>0</cast_shadows>
          <geometry>
            <plane>
              <normal>0 0 1</normal>
              <size>20 20</size>
            </plane>
          </geometry>
          <material>
            <script>
              <uri>model://grass_plane/materials/scripts</uri>
              <uri>model://grass_plane/materials/textures</uri>
              <name>vrc/grass</name>
            </script>
          </material>
        </visual>
        <visual name='visual_47'>
          <pose>60 80 0 0 -0 0</pose>
          <cast_shadows>0</cast_shadows>
          <geometry>
            <plane>
              <normal>0 0 1</normal>
              <size>20 20</size>
            </plane>
          </geometry>
          <material>
            <script>
              <uri>model://grass_plane/materials/scripts</uri>
              <uri>model://grass_plane/materials/textures</uri>
              <name>vrc/grass</name>
            </script>
          </material>
        </visual>
        <visual name='visual_48'>
          <pose>80 80 0 0 -0 0</pose>
          <cast_shadows>0</cast_shadows>
          <geometry>
            <plane>
              <normal>0 0 1</normal>
              <size>20 20</size>
            </plane>
          </geometry>
          <material>
            <script>
              <uri>model://grass_plane/materials/scripts</uri>
              <uri>model://grass_plane/materials/textures</uri>
              <name>vrc/grass</name>
            </script>
          </material>
        </visual>
        <visual name='visual_49'>
          <pose>100 80 0 0 -0 0</pose>
          <cast_shadows>0</cast_shadows>
          <geometry>
            <plane>
              <normal>0 0 1</normal>
              <size>20 20</size>
            </plane>
          </geometry>
          <material>
            <script>
              <uri>model://grass_plane/materials/scripts</uri>
              <uri>model://grass_plane/materials/textures</uri>
              <name>vrc/grass</name>
            </script>
          </material>
        </visual>
        <visual name='visual_50'>
          <pose>120 80 0 0 -0 0</pose>
          <cast_shadows>0</cast_shadows>
          <geometry>
            <plane>
              <normal>0 0 1</normal>
              <size>20 20</size>
            </plane>
          </geometry>
          <material>
            <script>
              <uri>model://grass_plane/materials/scripts</uri>
              <uri>model://grass_plane/materials/textures</uri>
              <name>vrc/grass</name>
            </script>
          </material>
        </visual>
        <visual name='visual_51'>
          <pose>140 80 0 0 -0 0</pose>
          <cast_shadows>0</cast_shadows>
          <geometry>
            <plane>
              <normal>0 0 1</normal>
              <size>20 20</size>
            </plane>
          </geometry>
          <material>
            <script>
              <uri>model://grass_plane/materials/scripts</uri>
              <uri>model://grass_plane/materials/textures</uri>
              <name>vrc/grass</name>
            </script>
          </material>
        </visual>
        <visual name='visual_52'>
          <pose>160 80 0 0 -0 0</pose>
          <cast_shadows>0</cast_shadows>
          <geometry>
            <plane>
              <normal>0 0 1</normal>
              <size>20 20</size>
            </plane>
          </geometry>
          <material>
            <script>
              <uri>model://grass_plane/materials/scripts</uri>
              <uri>model://grass_plane/materials/textures</uri>
              <name>vrc/grass</name>
            </script>
          </material>
        </visual>
        <visual name='visual_53'>
          <pose>180 80 0 0 -0 0</pose>
          <cast_shadows>0</cast_shadows>
          <geometry>
            <plane>
              <normal>0 0 1</normal>
              <size>20 20</size>
            </plane>
          </geometry>
          <material>
            <script>
              <uri>model://grass_plane/materials/scripts</uri>
              <uri>model://grass_plane/materials/textures</uri>
              <name>vrc/grass</name>
            </script>
          </material>
        </visual>
        <visual name='visual_54'>
          <pose>200 80 0 0 -0 0</pose>
          <cast_shadows>0</cast_shadows>
          <geometry>
            <plane>
              <normal>0 0 1</normal>
              <size>20 20</size>
            </plane>
          </geometry>
          <material>
            <script>
              <uri>model://grass_plane/materials/scripts</uri>
              <uri>model://grass_plane/materials/textures</uri>
              <name>vrc/grass</name>
            </script>
          </material>
        </visual>
        <visual name='visual_55'>
          <pose>40 100 0 0 -0 0</pose>
          <cast_shadows>0</cast_shadows>
          <geometry>
            <plane>
              <normal>0 0 1</normal>
              <size>20 20</size>
            </plane>
          </geometry>
          <material>
            <script>
              <uri>model://grass_plane/materials/scripts</uri>
              <uri>model://grass_plane/materials/textures</uri>
              <name>vrc/grass</name>
            </script>
          </material>
        </visual>
        <visual name='visual_56'>
          <pose>60 100 0 0 -0 0</pose>
          <cast_shadows>0</cast_shadows>
          <geometry>
            <plane>
              <normal>0 0 1</normal>
              <size>20 20</size>
            </plane>
          </geometry>
          <material>
            <script>
              <uri>model://grass_plane/materials/scripts</uri>
              <uri>model://grass_plane/materials/textures</uri>
              <name>vrc/grass</name>
            </script>
          </material>
        </visual>
        <visual name='visual_57'>
          <pose>80 100 0 0 -0 0</pose>
          <cast_shadows>0</cast_shadows>
          <geometry>
            <plane>
              <normal>0 0 1</normal>
              <size>20 20</size>
            </plane>
          </geometry>
          <material>
            <script>
              <uri>model://grass_plane/materials/scripts</uri>
              <uri>model://grass_plane/materials/textures</uri>
              <name>vrc/grass</name>
            </script>
          </material>
        </visual>
        <visual name='visual_58'>
          <pose>100 100 0 0 -0 0</pose>
          <cast_shadows>0</cast_shadows>
          <geometry>
            <plane>
              <normal>0 0 1</normal>
              <size>20 20</size>
            </plane>
          </geometry>
          <material>
            <script>
              <uri>model://grass_plane/materials/scripts</uri>
              <uri>model://grass_plane/materials/textures</uri>
              <name>vrc/grass</name>
            </script>
          </material>
        </visual>
        <visual name='visual_59'>
          <pose>120 100 0 0 -0 0</pose>
          <cast_shadows>0</cast_shadows>
          <geometry>
            <plane>
              <normal>0 0 1</normal>
              <size>20 20</size>
            </plane>
          </geometry>
          <material>
            <script>
              <uri>model://grass_plane/materials/scripts</uri>
              <uri>model://grass_plane/materials/textures</uri>
              <name>vrc/grass</name>
            </script>
          </material>
        </visual>
        <visual name='visual_60'>
          <pose>140 100 0 0 -0 0</pose>
          <cast_shadows>0</cast_shadows>
          <geometry>
            <plane>
              <normal>0 0 1</normal>
              <size>20 20</size>
            </plane>
          </geometry>
          <material>
            <script>
              <uri>model://grass_plane/materials/scripts</uri>
              <uri>model://grass_plane/materials/textures</uri>
              <name>vrc/grass</name>
            </script>
          </material>
        </visual>
        <visual name='visual_61'>
          <pose>160 100 0 0 -0 0</pose>
          <cast_shadows>0</cast_shadows>
          <geometry>
            <plane>
              <normal>0 0 1</normal>
              <size>20 20</size>
            </plane>
          </geometry>
          <material>
            <script>
              <uri>model://grass_plane/materials/scripts</uri>
              <uri>model://grass_plane/materials/textures</uri>
              <name>vrc/grass</name>
            </script>
          </material>
        </visual>
        <visual name='visual_62'>
          <pose>180 100 0 0 -0 0</pose>
          <cast_shadows>0</cast_shadows>
          <geometry>
            <plane>
              <normal>0 0 1</normal>
              <size>20 20</size>
            </plane>
          </geometry>
          <material>
            <script>
              <uri>model://grass_plane/materials/scripts</uri>
              <uri>model://grass_plane/materials/textures</uri>
              <name>vrc/grass</name>
            </script>
          </material>
        </visual>
        <visual name='visual_63'>
          <pose>200 100 0 0 -0 0</pose>
          <cast_shadows>0</cast_shadows>
          <geometry>
            <plane>
              <normal>0 0 1</normal>
              <size>20 20</size>
            </plane>
          </geometry>
          <material>
            <script>
              <uri>model://grass_plane/materials/scripts</uri>
              <uri>model://grass_plane/materials/textures</uri>
              <name>vrc/grass</name>
            </script>
          </material>
        </visual>
        <visual name='visual_63a'>
          <pose>220 100 0 0 -0 0</pose>
          <cast_shadows>0</cast_shadows>
          <geometry>
            <plane>
              <normal>0 0 1</normal>
              <size>20 20</size>
            </plane>
          </geometry>
          <material>
            <script>
              <uri>model://grass_plane/materials/scripts</uri>
              <uri>model://grass_plane/materials/textures</uri>
              <name>vrc/grass</name>
            </script>
          </material>
        </visual>
        <visual name='visual_64'>
          <pose>40 120 0 0 -0 0</pose>
          <cast_shadows>0</cast_shadows>
          <geometry>
            <plane>
              <normal>0 0 1</normal>
              <size>20 20</size>
            </plane>
          </geometry>
          <material>
            <script>
              <uri>model://grass_plane/materials/scripts</uri>
              <uri>model://grass_plane/materials/textures</uri>
              <name>vrc/grass</name>
            </script>
          </material>
        </visual>
        <visual name='visual_65'>
          <pose>60 120 0 0 -0 0</pose>
          <cast_shadows>0</cast_shadows>
          <geometry>
            <plane>
              <normal>0 0 1</normal>
              <size>20 20</size>
            </plane>
          </geometry>
          <material>
            <script>
              <uri>model://grass_plane/materials/scripts</uri>
              <uri>model://grass_plane/materials/textures</uri>
              <name>vrc/grass</name>
            </script>
          </material>
        </visual>
        <visual name='visual_66'>
          <pose>80 120 0 0 -0 0</pose>
          <cast_shadows>0</cast_shadows>
          <geometry>
            <plane>
              <normal>0 0 1</normal>
              <size>20 20</size>
            </plane>
          </geometry>
          <material>
            <script>
              <uri>model://grass_plane/materials/scripts</uri>
              <uri>model://grass_plane/materials/textures</uri>
              <name>vrc/grass</name>
            </script>
          </material>
        </visual>
        <visual name='visual_67'>
          <pose>100 120 0 0 -0 0</pose>
          <cast_shadows>0</cast_shadows>
          <geometry>
            <plane>
              <normal>0 0 1</normal>
              <size>20 20</size>
            </plane>
          </geometry>
          <material>
            <script>
              <uri>model://grass_plane/materials/scripts</uri>
              <uri>model://grass_plane/materials/textures</uri>
              <name>vrc/grass</name>
            </script>
          </material>
        </visual>
        <visual name='visual_68'>
          <pose>120 120 0 0 -0 0</pose>
          <cast_shadows>0</cast_shadows>
          <geometry>
            <plane>
              <normal>0 0 1</normal>
              <size>20 20</size>
            </plane>
          </geometry>
          <material>
            <script>
              <uri>model://grass_plane/materials/scripts</uri>
              <uri>model://grass_plane/materials/textures</uri>
              <name>vrc/grass</name>
            </script>
          </material>
        </visual>
        <visual name='visual_69'>
          <pose>140 120 0 0 -0 0</pose>
          <cast_shadows>0</cast_shadows>
          <geometry>
            <plane>
              <normal>0 0 1</normal>
              <size>20 20</size>
            </plane>
          </geometry>
          <material>
            <script>
              <uri>model://grass_plane/materials/scripts</uri>
              <uri>model://grass_plane/materials/textures</uri>
              <name>vrc/grass</name>
            </script>
          </material>
        </visual>
        <visual name='visual_70'>
          <pose>160 120 0 0 -0 0</pose>
          <cast_shadows>0</cast_shadows>
          <geometry>
            <plane>
              <normal>0 0 1</normal>
              <size>20 20</size>
            </plane>
          </geometry>
          <material>
            <script>
              <uri>model://grass_plane/materials/scripts</uri>
              <uri>model://grass_plane/materials/textures</uri>
              <name>vrc/grass</name>
            </script>
          </material>
        </visual>
        <visual name='visual_71'>
          <pose>180 120 0 0 -0 0</pose>
          <cast_shadows>0</cast_shadows>
          <geometry>
            <plane>
              <normal>0 0 1</normal>
              <size>20 20</size>
            </plane>
          </geometry>
          <material>
            <script>
              <uri>model://grass_plane/materials/scripts</uri>
              <uri>model://grass_plane/materials/textures</uri>
              <name>vrc/grass</name>
            </script>
          </material>
        </visual>
        <visual name='visual_72'>
          <pose>200 120 0 0 -0 0</pose>
          <cast_shadows>0</cast_shadows>
          <geometry>
            <plane>
              <normal>0 0 1</normal>
              <size>20 20</size>
            </plane>
          </geometry>
          <material>
            <script>
              <uri>model://grass_plane/materials/scripts</uri>
              <uri>model://grass_plane/materials/textures</uri>
              <name>vrc/grass</name>
            </script>
          </material>
        </visual>
        <visual name='visual_72a'>
          <pose>220 120 0 0 -0 0</pose>
          <cast_shadows>0</cast_shadows>
          <geometry>
            <plane>
              <normal>0 0 1</normal>
              <size>20 20</size>
            </plane>
          </geometry>
          <material>
            <script>
              <uri>model://grass_plane/materials/scripts</uri>
              <uri>model://grass_plane/materials/textures</uri>
              <name>vrc/grass</name>
            </script>
          </material>
        </visual>
        <visual name='visual_73'>
          <pose>40 140 0 0 -0 0</pose>
          <cast_shadows>0</cast_shadows>
          <geometry>
            <plane>
              <normal>0 0 1</normal>
              <size>20 20</size>
            </plane>
          </geometry>
          <material>
            <script>
              <uri>model://grass_plane/materials/scripts</uri>
              <uri>model://grass_plane/materials/textures</uri>
              <name>vrc/grass</name>
            </script>
          </material>
        </visual>
        <visual name='visual_74'>
          <pose>60 140 0 0 -0 0</pose>
          <cast_shadows>0</cast_shadows>
          <geometry>
            <plane>
              <normal>0 0 1</normal>
              <size>20 20</size>
            </plane>
          </geometry>
          <material>
            <script>
              <uri>model://grass_plane/materials/scripts</uri>
              <uri>model://grass_plane/materials/textures</uri>
              <name>vrc/grass</name>
            </script>
          </material>
        </visual>
        <visual name='visual_75'>
          <pose>80 140 0 0 -0 0</pose>
          <cast_shadows>0</cast_shadows>
          <geometry>
            <plane>
              <normal>0 0 1</normal>
              <size>20 20</size>
            </plane>
          </geometry>
          <material>
            <script>
              <uri>model://grass_plane/materials/scripts</uri>
              <uri>model://grass_plane/materials/textures</uri>
              <name>vrc/grass</name>
            </script>
          </material>
        </visual>
        <visual name='visual_76'>
          <pose>100 140 0 0 -0 0</pose>
          <cast_shadows>0</cast_shadows>
          <geometry>
            <plane>
              <normal>0 0 1</normal>
              <size>20 20</size>
            </plane>
          </geometry>
          <material>
            <script>
              <uri>model://grass_plane/materials/scripts</uri>
              <uri>model://grass_plane/materials/textures</uri>
              <name>vrc/grass</name>
            </script>
          </material>
        </visual>
        <visual name='visual_77'>
          <pose>120 140 0 0 -0 0</pose>
          <cast_shadows>0</cast_shadows>
          <geometry>
            <plane>
              <normal>0 0 1</normal>
              <size>20 20</size>
            </plane>
          </geometry>
          <material>
            <script>
              <uri>model://grass_plane/materials/scripts</uri>
              <uri>model://grass_plane/materials/textures</uri>
              <name>vrc/grass</name>
            </script>
          </material>
        </visual>
        <visual name='visual_78'>
          <pose>140 140 0 0 -0 0</pose>
          <cast_shadows>0</cast_shadows>
          <geometry>
            <plane>
              <normal>0 0 1</normal>
              <size>20 20</size>
            </plane>
          </geometry>
          <material>
            <script>
              <uri>model://grass_plane/materials/scripts</uri>
              <uri>model://grass_plane/materials/textures</uri>
              <name>vrc/grass</name>
            </script>
          </material>
        </visual>
        <visual name='visual_79'>
          <pose>160 140 0 0 -0 0</pose>
          <cast_shadows>0</cast_shadows>
          <geometry>
            <plane>
              <normal>0 0 1</normal>
              <size>20 20</size>
            </plane>
          </geometry>
          <material>
            <script>
              <uri>model://grass_plane/materials/scripts</uri>
              <uri>model://grass_plane/materials/textures</uri>
              <name>vrc/grass</name>
            </script>
          </material>
        </visual>
        <visual name='visual_80'>
          <pose>180 140 0 0 -0 0</pose>
          <cast_shadows>0</cast_shadows>
          <geometry>
            <plane>
              <normal>0 0 1</normal>
              <size>20 20</size>
            </plane>
          </geometry>
          <material>
            <script>
              <uri>model://grass_plane/materials/scripts</uri>
              <uri>model://grass_plane/materials/textures</uri>
              <name>vrc/grass</name>
            </script>
          </material>
        </visual>
        <visual name='visual_81'>
          <pose>200 140 0 0 -0 0</pose>
          <cast_shadows>0</cast_shadows>
          <geometry>
            <plane>
              <normal>0 0 1</normal>
              <size>20 20</size>
            </plane>
          </geometry>
          <material>
            <script>
              <uri>model://grass_plane/materials/scripts</uri>
              <uri>model://grass_plane/materials/textures</uri>
              <name>vrc/grass</name>
            </script>
          </material>
        </visual>
        <visual name='visual_82'>
          <pose>40 160 0 0 -0 0</pose>
          <cast_shadows>0</cast_shadows>
          <geometry>
            <plane>
              <normal>0 0 1</normal>
              <size>20 20</size>
            </plane>
          </geometry>
          <material>
            <script>
              <uri>model://grass_plane/materials/scripts</uri>
              <uri>model://grass_plane/materials/textures</uri>
              <name>vrc/grass</name>
            </script>
          </material>
        </visual>
        <visual name='visual_83'>
          <pose>60 160 0 0 -0 0</pose>
          <cast_shadows>0</cast_shadows>
          <geometry>
            <plane>
              <normal>0 0 1</normal>
              <size>20 20</size>
            </plane>
          </geometry>
          <material>
            <script>
              <uri>model://grass_plane/materials/scripts</uri>
              <uri>model://grass_plane/materials/textures</uri>
              <name>vrc/grass</name>
            </script>
          </material>
        </visual>
        <visual name='visual_84'>
          <pose>80 160 0 0 -0 0</pose>
          <cast_shadows>0</cast_shadows>
          <geometry>
            <plane>
              <normal>0 0 1</normal>
              <size>20 20</size>
            </plane>
          </geometry>
          <material>
            <script>
              <uri>model://grass_plane/materials/scripts</uri>
              <uri>model://grass_plane/materials/textures</uri>
              <name>vrc/grass</name>
            </script>
          </material>
        </visual>
        <visual name='visual_85'>
          <pose>100 160 0 0 -0 0</pose>
          <cast_shadows>0</cast_shadows>
          <geometry>
            <plane>
              <normal>0 0 1</normal>
              <size>20 20</size>
            </plane>
          </geometry>
          <material>
            <script>
              <uri>model://grass_plane/materials/scripts</uri>
              <uri>model://grass_plane/materials/textures</uri>
              <name>vrc/grass</name>
            </script>
          </material>
        </visual>
        <visual name='visual_86'>
          <pose>120 160 0 0 -0 0</pose>
          <cast_shadows>0</cast_shadows>
          <geometry>
            <plane>
              <normal>0 0 1</normal>
              <size>20 20</size>
            </plane>
          </geometry>
          <material>
            <script>
              <uri>model://grass_plane/materials/scripts</uri>
              <uri>model://grass_plane/materials/textures</uri>
              <name>vrc/grass</name>
            </script>
          </material>
        </visual>
        <velocity_decay>
          <linear>0</linear>
          <angular>0</angular>
        </velocity_decay>
        <self_collide>0</self_collide>
        <kinematic>0</kinematic>
        <gravity>1</gravity>
      </link>
    </model>
    <model name='vilma_vehicle'>
      <link name='vilma_draw::chassis'>
        <inertial>
          <mass>1261.3</mass>
          <inertia>
            <ixx>897.368</ixx>
            <ixy>0</ixy>
            <iyy>1825.06</iyy>
            <ixz>0</ixz>
            <iyz>0</iyz>
            <izz>2722.43</izz>
          </inertia>
          <pose>0.358 0.0435 0.93675 0 -0 0</pose>
        </inertial>
        <visual name='visual'>
          <pose>-3.58 -2.465 -0.3 0 -0 0</pose>
          <geometry>
            <mesh>
              <uri>model://vilma_draw/Fiatpuntosinruedas2.dae</uri>
              <scale>1 1 1</scale>
            </mesh>
          </geometry>
        </visual>
        <collision name='vilma_draw::chassis'>
          <pose>0 0 0.74625 0 -0 0</pose>
          <geometry>
            <box>
              <size>2.4 1.687 0.7</size>
            </box>
          </geometry>
          <max_contacts>10</max_contacts>
          <surface>
            <bounce/>
            <friction>
              <ode/>
            </friction>
            <contact>
              <ode/>
            </contact>
          </surface>
        </collision>
        <velocity_decay>
          <linear>0</linear>
          <angular>0</angular>
        </velocity_decay>
        <pose>0 0 0 0 -0 0</pose>
        <self_collide>0</self_collide>
        <kinematic>0</kinematic>
        <gravity>1</gravity>
      </link>
      <link name='vilma_draw::rear_right_wheel'>
        <pose>-1.2505 -0.735 0.32 1.52 -0 0</pose>
        <inertial>
          <mass>12</mass>
          <inertia>
            <ixx>0.160731</ixx>
            <ixy>0</ixy>
            <iyy>0.22815</iyy>
            <ixz>0</ixz>
            <iyz>0</iyz>
            <izz>0.160731</izz>
          </inertia>
        </inertial>
        <collision name='collision'>
          <geometry>
            <cylinder>
              <radius>0.381</radius>
              <length>0.216</length>
            </cylinder>
          </geometry>
          <max_contacts>1</max_contacts>
          <surface>
            <friction>
              <ode>
                <mu>1</mu>
                <mu2>1</mu2>
                <fdir1>0 0 1</fdir1>
                <slip1>0</slip1>
                <slip2>0</slip2>
              </ode>
            </friction>
            <contact>
              <ode>
                <min_depth>0.005</min_depth>
                <kp>1e+08</kp>
              </ode>
            </contact>
            <bounce/>
          </surface>
        </collision>
        <visual name='visual'>
          <pose>0 0 0 3.14159 -1.57079 3.14159</pose>
          <geometry>
            <mesh>
              <uri>model://vilma_draw/meshes/polaris.dae</uri>
              <submesh>
                <name>Rear_Wheel_Right</name>
                <center>1</center>
              </submesh>
            </mesh>
          </geometry>
        </visual>
        <velocity_decay>
          <linear>0</linear>
          <angular>0</angular>
        </velocity_decay>
        <self_collide>0</self_collide>
        <kinematic>0</kinematic>
        <gravity>1</gravity>
      </link>
      <link name='vilma_draw::rear_left_wheel'>
        <pose>-1.2505 0.735 0.32 -1.52 0 0</pose>
        <inertial>
          <mass>12</mass>
          <inertia>
            <ixx>0.160731</ixx>
            <ixy>0</ixy>
            <iyy>0.22815</iyy>
            <ixz>0</ixz>
            <iyz>0</iyz>
            <izz>0.160731</izz>
          </inertia>
        </inertial>
        <collision name='collision'>
          <geometry>
            <cylinder>
              <radius>0.381</radius>
              <length>0.216</length>
            </cylinder>
          </geometry>
          <max_contacts>1</max_contacts>
          <surface>
            <friction>
              <ode>
                <mu>1</mu>
                <mu2>1</mu2>
                <fdir1>0 0 1</fdir1>
                <slip1>0</slip1>
                <slip2>0</slip2>
              </ode>
            </friction>
            <contact>
              <ode>
                <min_depth>0.005</min_depth>
                <kp>1e+08</kp>
              </ode>
            </contact>
            <bounce/>
          </surface>
        </collision>
        <visual name='visual'>
          <pose>0 0 0 3.14159 -1.57079 3.14159</pose>
          <geometry>
            <mesh>
              <uri>model://vilma_draw/meshes/polaris.dae</uri>
              <submesh>
                <name>Rear_Wheel_Left</name>
                <center>1</center>
              </submesh>
            </mesh>
          </geometry>
        </visual>
        <velocity_decay>
          <linear>0</linear>
          <angular>0</angular>
        </velocity_decay>
        <self_collide>0</self_collide>
        <kinematic>0</kinematic>
        <gravity>1</gravity>
      </link>
      <link name='vilma_draw::front_right_wheel'>
        <pose>1.2505 -0.735 0.32 1.52 -0 0</pose>
        <inertial>
          <mass>12</mass>
          <inertia>
            <ixx>0.160731</ixx>
            <ixy>0</ixy>
            <iyy>0.22815</iyy>
            <ixz>0</ixz>
            <iyz>0</iyz>
            <izz>0.160731</izz>
          </inertia>
        </inertial>
        <collision name='collision'>
          <geometry>
            <cylinder>
              <radius>0.381</radius>
              <length>0.216</length>
            </cylinder>
          </geometry>
          <max_contacts>1</max_contacts>
          <surface>
            <friction>
              <ode>
                <mu>1</mu>
                <mu2>1</mu2>
                <fdir1>0 0 1</fdir1>
                <slip1>0</slip1>
                <slip2>0</slip2>
              </ode>
            </friction>
            <contact>
              <ode>
                <min_depth>0.005</min_depth>
                <kp>1e+08</kp>
              </ode>
            </contact>
            <bounce/>
          </surface>
        </collision>
        <visual name='visual'>
          <pose>0 0 0 3.14159 -1.57079 3.14159</pose>
          <geometry>
            <mesh>
              <uri>model://vilma_draw/meshes/polaris.dae</uri>
              <submesh>
                <name>Front_Wheel_Right</name>
                <center>1</center>
              </submesh>
            </mesh>
          </geometry>
        </visual>
        <velocity_decay>
          <linear>0</linear>
          <angular>0</angular>
        </velocity_decay>
        <self_collide>0</self_collide>
        <kinematic>0</kinematic>
        <gravity>1</gravity>
      </link>
      <link name='vilma_draw::front_right_wheel_steering_block'>
        <pose>1.25 -0.635 0.32 1.5708 -0 0</pose>
        <inertial>
          <mass>1</mass>
          <inertia>
            <ixx>1</ixx>
            <ixy>0</ixy>
            <iyy>1</iyy>
            <ixz>0</ixz>
            <iyz>0</iyz>
            <izz>1</izz>
          </inertia>
        </inertial>
        <collision name='collision'>
          <geometry>
            <cylinder>
              <radius>0.05</radius>
              <length>0.01</length>
            </cylinder>
          </geometry>
          <max_contacts>10</max_contacts>
          <surface>
            <bounce/>
            <friction>
              <ode/>
            </friction>
            <contact>
              <ode/>
            </contact>
          </surface>
        </collision>
        <velocity_decay>
          <linear>0</linear>
          <angular>0</angular>
        </velocity_decay>
        <self_collide>0</self_collide>
        <kinematic>0</kinematic>
        <gravity>1</gravity>
      </link>
      <link name='vilma_draw::front_left_wheel'>
        <pose>1.2505 0.735 0.32 -1.52 0 0</pose>
        <inertial>
          <mass>12</mass>
          <inertia>
            <ixx>0.160731</ixx>
            <ixy>0</ixy>
            <iyy>0.22815</iyy>
            <ixz>0</ixz>
            <iyz>0</iyz>
            <izz>0.160731</izz>
          </inertia>
        </inertial>
        <collision name='collision'>
          <geometry>
            <cylinder>
              <radius>0.381</radius>
              <length>0.216</length>
            </cylinder>
          </geometry>
          <max_contacts>1</max_contacts>
          <surface>
            <friction>
              <ode>
                <mu>1</mu>
                <mu2>1</mu2>
                <fdir1>0 0 1</fdir1>
                <slip1>0</slip1>
                <slip2>0</slip2>
              </ode>
            </friction>
            <contact>
              <ode>
                <min_depth>0.005</min_depth>
                <kp>1e+08</kp>
              </ode>
            </contact>
            <bounce/>
          </surface>
        </collision>
        <visual name='visual'>
          <pose>0 0 0 -2.65359e-06 1.57079 3.14159</pose>
          <geometry>
            <mesh>
              <uri>model://vilma_draw/meshes/polaris.dae</uri>
              <submesh>
                <name>Front_Wheel_Left</name>
                <center>1</center>
              </submesh>
            </mesh>
          </geometry>
        </visual>
        <velocity_decay>
          <linear>0</linear>
          <angular>0</angular>
        </velocity_decay>
        <self_collide>0</self_collide>
        <kinematic>0</kinematic>
        <gravity>1</gravity>
      </link>
      <link name='vilma_draw::front_left_wheel_steering_block'>
        <pose>1.2505 0.635 0.32 1.5708 -0 0</pose>
        <inertial>
          <mass>1</mass>
          <inertia>
            <ixx>1</ixx>
            <ixy>0</ixy>
            <iyy>1</iyy>
            <ixz>0</ixz>
            <iyz>0</iyz>
            <izz>1</izz>
          </inertia>
        </inertial>
        <collision name='collision'>
          <geometry>
            <cylinder>
              <radius>0.05</radius>
              <length>0.01</length>
            </cylinder>
          </geometry>
          <max_contacts>10</max_contacts>
          <surface>
            <bounce/>
            <friction>
              <ode/>
            </friction>
            <contact>
              <ode/>
            </contact>
          </surface>
        </collision>
        <velocity_decay>
          <linear>0</linear>
          <angular>0</angular>
        </velocity_decay>
        <self_collide>0</self_collide>
        <kinematic>0</kinematic>
        <gravity>1</gravity>
      </link>
      <link name='vilma_draw::gas_pedal'>
        <pose>0.63 0.1 2 0 -0 0</pose>
        <gravity>0</gravity>
        <inertial>
          <mass>0.1</mass>
          <pose>0 0 0 0 -0 0</pose>
          <inertia>
            <ixx>0.01</ixx>
            <ixy>0</ixy>
            <ixz>0</ixz>
            <iyy>0.01</iyy>
            <iyz>0</iyz>
            <izz>0.01</izz>
          </inertia>
        </inertial>
        <collision name='gas_pedal_collision'>
          <pose>-0.0385 0 -0.086 3.14159 1.12559 3.14159</pose>
          <geometry>
            <box>
              <size>0.1069 0.077 0.01</size>
            </box>
          </geometry>
          <max_contacts>10</max_contacts>
          <surface>
            <bounce/>
            <friction>
              <ode/>
            </friction>
            <contact>
              <ode/>
            </contact>
          </surface>
        </collision>
        <visual name='visual'>
          <pose>0 0 0 0 0 -1.5707</pose>
          <geometry>
            <mesh>
              <uri>model://vilma_draw/meshes/polaris.dae</uri>
              <submesh>
                <name>Pedal_Gas</name>
                <center>1</center>
              </submesh>
            </mesh>
          </geometry>
        </visual>
        <velocity_decay>
          <linear>0</linear>
          <angular>0</angular>
        </velocity_decay>
        <self_collide>0</self_collide>
        <kinematic>0</kinematic>
      </link>
      <link name='vilma_draw::brake_pedal'>
        <gravity>0</gravity>
        <pose>0.64 0.27 2 0 -0 0</pose>
        <inertial>
          <mass>0.1</mass>
          <pose>0 0 0 0 -0 0</pose>
          <inertia>
            <ixx>0.01</ixx>
            <ixy>0</ixy>
            <ixz>0</ixz>
            <iyy>0.01</iyy>
            <iyz>0</iyz>
            <izz>0.01</izz>
          </inertia>
        </inertial>
        <collision name='brake_pedal_collision'>
          <pose>-0.04 0 -0.086 3.14159 1.14259 3.14159</pose>
          <geometry>
            <box>
              <size>0.063 0.08 0.01</size>
            </box>
          </geometry>
          <max_contacts>10</max_contacts>
          <surface>
            <bounce/>
            <friction>
              <ode/>
            </friction>
            <contact>
              <ode/>
            </contact>
          </surface>
        </collision>
        <visual name='visual'>
          <pose>0 0 0 0 0 -1.5707</pose>
          <geometry>
            <mesh>
              <uri>model://vilma_draw/meshes/polaris.dae</uri>
              <submesh>
                <name>Pedal_brake</name>
                <center>1</center>
              </submesh>
            </mesh>
          </geometry>
        </visual>
        <velocity_decay>
          <linear>0</linear>
          <angular>0</angular>
        </velocity_decay>
        <self_collide>0</self_collide>
        <kinematic>0</kinematic>
      </link>
      <link name='vilma_draw::steering_wheel'>
        <pose>0.34 0.3 2 0 -0.87 0</pose>
        <inertial>
          <mass>1</mass>
          <pose>-0.002 0 0 0 -0 0</pose>
          <inertia>
            <ixx>0.012</ixx>
            <ixy>0</ixy>
            <ixz>0</ixz>
            <iyy>0.012</iyy>
            <iyz>0</iyz>
            <izz>0.024</izz>
          </inertia>
        </inertial>
        <collision name='collision'>
          <pose>0 0 0 -0.69 5.55112e-17 -1.5708</pose>
          <geometry>
            <mesh>
              <uri>model://vilma_draw/meshes/polaris.dae</uri>
              <submesh>
                <name>Steering_Wheel</name>
                <center>1</center>
              </submesh>
            </mesh>
          </geometry>
          <surface>
            <contact>
              <ode>
                <min_depth>0.003</min_depth>
              </ode>
            </contact>
            <bounce/>
            <friction>
              <ode/>
            </friction>
          </surface>
          <max_contacts>10</max_contacts>
        </collision>
        <visual name='visual'>
          <pose>0 0 0 -0.69 5.55112e-17 -1.5708</pose>
          <geometry>
            <mesh>
              <uri>model://vilma_draw/meshes/polaris.dae</uri>
              <submesh>
                <name>Steering_Wheel</name>
                <center>1</center>
              </submesh>
            </mesh>
          </geometry>
        </visual>
        <velocity_decay>
          <linear>0</linear>
          <angular>0</angular>
        </velocity_decay>
        <self_collide>0</self_collide>
        <kinematic>0</kinematic>
        <gravity>1</gravity>
      </link>
      <link name='vilma_draw::hand_brake'>
        <pose>0.5 0 1.05 3.14159 -0.0584073 3.14159</pose>
        <inertial>
          <mass>0.5</mass>
          <inertia>
            <ixx>0.1</ixx>
            <ixy>0</ixy>
            <ixz>0</ixz>
            <iyy>0.1</iyy>
            <iyz>0</iyz>
            <izz>0.05</izz>
          </inertia>
        </inertial>
        <collision name='hand_brake_collision'>
          <pose>0 0 -0.1 0 -0 0</pose>
          <geometry>
            <cylinder>
              <radius>0.01</radius>
              <length>0.2</length>
            </cylinder>
          </geometry>
          <max_contacts>10</max_contacts>
          <surface>
            <bounce/>
            <friction>
              <ode/>
            </friction>
            <contact>
              <ode/>
            </contact>
          </surface>
        </collision>
        <visual name='hand_brake_visual'>
          <pose>0 0 -0.1 0 -0 0</pose>
          <geometry>
            <cylinder>
              <radius>0.01</radius>
              <length>0.2</length>
            </cylinder>
          </geometry>
          <material>
            <script>
              <uri>file://media/materials/scripts/gazebo.material</uri>
              <name>Gazebo/Wood</name>
            </script>
          </material>
        </visual>
        <velocity_decay>
          <linear>0</linear>
          <angular>0</angular>
        </velocity_decay>
        <self_collide>0</self_collide>
        <kinematic>0</kinematic>
        <gravity>1</gravity>
      </link>
      <link name='vilma_draw::FNR_switch'>
        <pose>0.56 -0.02 2 0 0.25 0</pose>
        <inertial>
          <mass>0.1</mass>
          <inertia>
            <ixx>0.1</ixx>
            <ixy>0</ixy>
            <ixz>0</ixz>
            <iyy>6e-05</iyy>
            <iyz>0</iyz>
            <izz>0.1</izz>
          </inertia>
        </inertial>
        <collision name='vilma_draw::FNR_switch'>
          <geometry>
            <box>
              <size>0.02 0.04 0.08</size>
            </box>
          </geometry>
          <max_contacts>10</max_contacts>
          <surface>
            <bounce/>
            <friction>
              <ode/>
            </friction>
            <contact>
              <ode/>
            </contact>
          </surface>
        </collision>
        <visual name='FNR_switch_F'>
          <transparency>0</transparency>
          <geometry>
            <box>
              <size>0.02 0.04 0.08</size>
            </box>
          </geometry>
          <material>
            <script>
              <uri>model://vilma_draw/materials/scripts</uri>
              <uri>model://vilma_draw/materials/textures</uri>
              <name>FNR_switch_F</name>
            </script>
          </material>
        </visual>
        <visual name='FNR_switch_R'>
          <transparency>1</transparency>
          <geometry>
            <box>
              <size>0.0199 0.0399 0.0799</size>
            </box>
          </geometry>
          <material>
            <script>
              <uri>model://vilma_draw/materials/scripts</uri>
              <uri>model://vilma_draw/materials/textures</uri>
              <name>FNR_switch_R</name>
            </script>
          </material>
        </visual>
        <velocity_decay>
          <linear>0</linear>
          <angular>0</angular>
        </velocity_decay>
        <self_collide>0</self_collide>
        <kinematic>0</kinematic>
        <gravity>1</gravity>
      </link>
      <joint name='vilma_draw::front_left_steering_joint' type='revolute'>
        <child>vilma_draw::front_left_wheel_steering_block</child>
        <parent>vilma_draw::chassis</parent>
        <axis>
          <xyz>0 0 1</xyz>
          <limit>
            <lower>-0.8727</lower>
            <upper>0.8727</upper>
          </limit>
          <dynamics>
            <damping>50</damping>
          </dynamics>
        </axis>
        <physics>
          <ode>
            <cfm_damping>1</cfm_damping>
            <limit>
              <cfm>0</cfm>
              <erp>0.9</erp>
            </limit>
          </ode>
        </physics>
      </joint>
      <joint name='vilma_draw::front_left_wheel_joint' type='revolute'>
        <child>vilma_draw::front_left_wheel</child>
        <parent>vilma_draw::front_left_wheel_steering_block</parent>
        <axis>
          <xyz>0 1 0.05</xyz>
          <limit>
            <lower>0</lower>
            <upper>0</upper>
          </limit>
        </axis>
      </joint>
      <joint name='vilma_draw::front_right_steering_joint' type='revolute'>
        <child>vilma_draw::front_right_wheel_steering_block</child>
        <parent>vilma_draw::chassis</parent>
        <axis>
          <xyz>0 0 1</xyz>
          <limit>
            <lower>-0.8727</lower>
            <upper>0.8727</upper>
          </limit>
          <dynamics>
            <damping>50</damping>
          </dynamics>
        </axis>
        <physics>
          <ode>
            <cfm_damping>1</cfm_damping>
            <limit>
              <cfm>0</cfm>
              <erp>0.9</erp>
            </limit>
          </ode>
        </physics>
      </joint>
      <joint name='vilma_draw::front_right_wheel_joint' type='revolute'>
        <child>vilma_draw::front_right_wheel</child>
        <parent>vilma_draw::front_right_wheel_steering_block</parent>
        <axis>
          <xyz>0 1 -0.05</xyz>
          <limit>
            <lower>0</lower>
            <upper>0</upper>
          </limit>
        </axis>
      </joint>
      <joint name='vilma_draw::rear_left_wheel_joint' type='revolute'>
        <child>vilma_draw::rear_left_wheel</child>
        <parent>vilma_draw::chassis</parent>
        <axis>
          <xyz>0 1 0.05</xyz>
          <limit>
            <lower>0</lower>
            <upper>0</upper>
          </limit>
        </axis>
      </joint>
      <joint name='vilma_draw::rear_right_wheel_joint' type='revolute'>
        <pose>0 0 -0.1 0 -0 0</pose>
        <child>vilma_draw::rear_right_wheel</child>
        <parent>vilma_draw::chassis</parent>
        <axis>
          <xyz>0 1 -0.05</xyz>
          <limit>
            <lower>0</lower>
            <upper>0</upper>
          </limit>
        </axis>
      </joint>
      <joint name='vilma_draw::rear_differential_joint' type='revolute'>
        <child>vilma_draw::rear_right_wheel</child>
        <parent>vilma_draw::rear_left_wheel</parent>
        <axis>
          <xyz>0 1 0</xyz>
          <dynamics>
            <damping>70</damping>
          </dynamics>
          <limit>
            <lower>-1e+16</lower>
            <upper>1e+16</upper>
          </limit>
        </axis>
        <physics>
          <ode>
            <erp>0</erp>
            <cfm>1000</cfm>
            <cfm_damping>1</cfm_damping>
            <limit>
              <cfm>0</cfm>
              <erp>0.2</erp>
            </limit>
          </ode>
        </physics>
      </joint>
      <joint name='vilma_draw::gas_joint' type='prismatic'>
        <parent>vilma_draw::chassis</parent>
        <child>vilma_draw::gas_pedal</child>
        <axis>
          <xyz>1 0 -1</xyz>
          <limit>
            <lower>0</lower>
            <upper>0.08</upper>
          </limit>
          <dynamics>
            <damping>3</damping>
          </dynamics>
        </axis>
        <physics>
          <ode>
            <cfm_damping>1</cfm_damping>
            <limit>
              <cfm>0</cfm>
              <erp>0.2</erp>
            </limit>
          </ode>
        </physics>
      </joint>
      <joint name='vilma_draw::brake_joint' type='prismatic'>
        <parent>vilma_draw::chassis</parent>
        <child>vilma_draw::brake_pedal</child>
        <axis>
          <xyz>1 0 -0.6</xyz>
          <limit>
            <lower>0</lower>
            <upper>0.08</upper>
          </limit>
          <dynamics>
            <damping>3</damping>
          </dynamics>
        </axis>
        <physics>
          <ode>
            <cfm_damping>1</cfm_damping>
            <limit>
              <cfm>0</cfm>
              <erp>0.2</erp>
            </limit>
          </ode>
        </physics>
      </joint>
      <joint name='vilma_draw::steering_joint' type='revolute'>
        <pose>-0.002 0 0 0 -0 0</pose>
        <parent>vilma_draw::chassis</parent>
        <child>vilma_draw::steering_wheel</child>
        <axis>
          <xyz>-1 0 0.84365</xyz>
          <limit>
            <lower>-3.14</lower>
            <upper>3.14</upper>
          </limit>
          <dynamics>
            <damping>1</damping>
          </dynamics>
        </axis>
        <physics>
          <ode>
            <cfm_damping>1</cfm_damping>
            <limit>
              <cfm>0</cfm>
              <erp>0.2</erp>
            </limit>
          </ode>
        </physics>
      </joint>
      <joint name='vilma_draw::hand_brake_joint' type='revolute'>
        <parent>vilma_draw::chassis</parent>
        <child>vilma_draw::hand_brake</child>
        <axis>
          <xyz>0 -1 0</xyz>
          <limit>
            <lower>0</lower>
            <upper>0.6</upper>
          </limit>
          <dynamics>
            <damping>1</damping>
          </dynamics>
        </axis>
        <physics>
          <ode>
            <cfm_damping>1</cfm_damping>
            <limit>
              <cfm>0</cfm>
              <erp>0.2</erp>
            </limit>
          </ode>
        </physics>
      </joint>
      <joint name='vilma_draw::FNR_switch_joint' type='revolute'>
        <parent>vilma_draw::chassis</parent>
        <child>vilma_draw::FNR_switch</child>
        <axis>
          <xyz>0 -1 0</xyz>
          <limit>
            <lower>-0.3</lower>
            <upper>0.3</upper>
          </limit>
          <dynamics>
            <damping>0.01</damping>
          </dynamics>
        </axis>
        <physics>
          <ode>
            <cfm_damping>1</cfm_damping>
            <limit>
              <cfm>0</cfm>
              <erp>0.2</erp>
            </limit>
          </ode>
        </physics>
      </joint>
      <link name='camera_front'>
        <gravity>0</gravity>
        <pose>1.5 0 1 0 -0 0</pose>
        <inertial>
          <mass>0.1</mass>
          <inertia>
            <ixx>1</ixx>
            <ixy>0</ixy>
            <ixz>0</ixz>
            <iyy>1</iyy>
            <iyz>0</iyz>
            <izz>1</izz>
          </inertia>
        </inertial>
        <visual name='visual'>
          <geometry>
            <box>
              <size>0.1 0.1 0.1</size>
            </box>
          </geometry>
        </visual>
        <sensor name='camera' type='multicamera'>
          <always_on>1</always_on>
          <update_rate>20</update_rate>
          <visualize>0</visualize>
          <camera name='left'>
            <pose>0 0.2 0 0 -0 0</pose>
            <horizontal_fov>1.047</horizontal_fov>
            <image>
              <width>320</width>
              <height>240</height>
            </image>
            <clip>
              <near>0.1</near>
              <far>100</far>
            </clip>
            <save enabled='0'>
              <path>images/video2</path>
            </save>
          </camera>
          <camera name='right'>
            <pose>0 -0.2 0 0 -0 0</pose>
            <horizontal_fov>1.047</horizontal_fov>
            <image>
              <width>320</width>
              <height>240</height>
            </image>
            <clip>
              <near>0.1</near>
              <far>100</far>
            </clip>
            <save enabled='0'>
              <path>images/video2</path>
            </save>
          </camera>
          <plugin name='camera_en_ros' filename='libgazebo_ros_multicamera.so'>
            <cameraName>vilma_front</cameraName>
            <imageTopicName>image</imageTopicName>
            <cameraInfoTopicName>vilma_camera_info</cameraInfoTopicName>
            <frameName>Vilma_front</frameName>
            <updateRate>30.0</updateRate>
            <Cy>0</Cy>
            <Cx>0</Cx>
            <CxPrime>0</CxPrime>
          </plugin>
        </sensor>
        <velocity_decay>
          <linear>0</linear>
          <angular>0</angular>
        </velocity_decay>
        <self_collide>0</self_collide>
        <kinematic>0</kinematic>
      </link>
      <joint name='camera_front_joint' type='revolute'>
        <child>camera_front</child>
        <parent>vilma_draw::chassis</parent>
        <axis>
          <xyz>0 0 1</xyz>
          <limit>
            <upper>0</upper>
            <lower>0</lower>
          </limit>
        </axis>
      </joint>
      <plugin name='vehicle' filename='libvilma_ros_plugin.so'>
        <front_left_wheel>vilma_draw::front_left_wheel_joint</front_left_wheel>
        <front_right_wheel>vilma_draw::front_right_wheel_joint</front_right_wheel>
        <front_left_wheel_steering>vilma_draw::front_left_steering_joint</front_left_wheel_steering>
        <front_right_wheel_steering>vilma_draw::front_right_steering_joint</front_right_wheel_steering>
        <back_left_wheel>vilma_draw::rear_left_wheel_joint</back_left_wheel>
        <back_right_wheel>vilma_draw::rear_right_wheel_joint</back_right_wheel>
        <gas_pedal>vilma_draw::gas_joint</gas_pedal>
        <brake_pedal>vilma_draw::brake_joint</brake_pedal>
        <steering_wheel>vilma_draw::steering_joint</steering_wheel>
        <hand_brake>vilma_draw::hand_brake_joint</hand_brake>
        <fnr_switch>vilma_draw::FNR_switch_joint</fnr_switch>
        <fnr_switch_f>vilma_draw::FNR_switch::FNR_switch_F</fnr_switch_f>
        <fnr_switch_r>vilma_draw::FNR_switch::FNR_switch_R</fnr_switch_r>
        <front_torque>1000</front_torque>
        <back_torque>0</back_torque>
        <front_brake_torque>2000</front_brake_torque>
        <back_brake_torque>2000</back_brake_torque>
        <tire_angle_range>0.5</tire_angle_range>
        <max_speed>20</max_speed>
        <max_steer>0.6458</max_steer>
        <aero_load>0.1</aero_load>
        <min_brake_percent>0.04</min_brake_percent>
      </plugin>
      <plugin name='imu_en_ros' filename='libgazebo_ros_imu.so'>
        <bodyName>vilma_draw::chassis</bodyName>
        <topicName>vilma_vehicle/imu</topicName>
        <gaussianNoise>0.0</gaussianNoise>
        <xyzOffset>0 0 0.0</xyzOffset>
        <rpyOffset>0 0 0</rpyOffset>
      </plugin>
      <pose>-19 -20 0 0 -0 0</pose>
      <static>0</static>
    </model>
    <spherical_coordinates>
      <surface_model>EARTH_WGS84</surface_model>
      <latitude_deg>0</latitude_deg>
      <longitude_deg>0</longitude_deg>
      <elevation>0</elevation>
      <heading_deg>0</heading_deg>
    </spherical_coordinates>
    <model name='road'>
      <static>1</static>
      <pose>-24 -18 0 0 -0 0</pose>
      <link name='link'>
        <visual name='visual'>
          <pose>0 0 0.005 0 -0 0</pose>
          <geometry>
            <mesh>
              <uri>model://road/road.dae</uri>
            </mesh>
          </geometry>
        </visual>
        <velocity_decay>
          <linear>0</linear>
          <angular>0</angular>
        </velocity_decay>
        <self_collide>0</self_collide>
        <kinematic>0</kinematic>
        <gravity>1</gravity>
      </link>
    </model>
    <model name='road_0'>
      <static>1</static>
      <pose>-14.4828 -18 0 0 -0 0</pose>
      <link name='link'>
        <visual name='visual'>
          <pose>0 0 0.005 0 -0 0</pose>
          <geometry>
            <mesh>
              <uri>model://road/road.dae</uri>
            </mesh>
          </geometry>
        </visual>
        <velocity_decay>
          <linear>0</linear>
          <angular>0</angular>
        </velocity_decay>
        <self_collide>0</self_collide>
        <kinematic>0</kinematic>
        <gravity>1</gravity>
      </link>
    </model>
    <model name='road_1'>
      <static>1</static>
      <pose>-5 -18 0 0 -0 0</pose>
      <link name='link'>
        <visual name='visual'>
          <pose>0 0 0.005 0 -0 0</pose>
          <geometry>
            <mesh>
              <uri>model://road/road.dae</uri>
            </mesh>
          </geometry>
        </visual>
        <velocity_decay>
          <linear>0</linear>
          <angular>0</angular>
        </velocity_decay>
        <self_collide>0</self_collide>
        <kinematic>0</kinematic>
        <gravity>1</gravity>
      </link>
    </model>
    <model name='road_2'>
      <static>1</static>
      <pose>4.49281 -18 0 0 -0 0</pose>
      <link name='link'>
        <visual name='visual'>
          <pose>0 0 0.005 0 -0 0</pose>
          <geometry>
            <mesh>
              <uri>model://road/road.dae</uri>
            </mesh>
          </geometry>
        </visual>
        <velocity_decay>
          <linear>0</linear>
          <angular>0</angular>
        </velocity_decay>
        <self_collide>0</self_collide>
        <kinematic>0</kinematic>
        <gravity>1</gravity>
      </link>
    </model>
    <model name='Road_cure_right2'>
      <static>1</static>
      <pose>15 -18.5458 0 0 -0 0</pose>
      <link name='link'>
        <visual name='visual'>
          <pose>-0.14 0 -0.06 0 -0 0</pose>
          <geometry>
            <mesh>
              <uri>model://Road_Curve_right2/Road_Curve_right2.dae</uri>
            </mesh>
          </geometry>
        </visual>
        <velocity_decay>
          <linear>0</linear>
          <angular>0</angular>
        </velocity_decay>
        <self_collide>0</self_collide>
        <kinematic>0</kinematic>
        <gravity>1</gravity>
      </link>
    </model>
    <model name='Road_cure_left2'>
      <static>1</static>
      <pose>15 -28 0 0 -0 0</pose>
      <link name='link'>
        <visual name='visual'>
          <pose>0.16 0 -0.05 0 -0 0</pose>
          <geometry>
            <mesh>
              <uri>model://Road_Curve_left2/Road_Curve_left2.dae</uri>
              <scale>0.995 0.995 0.995</scale>
            </mesh>
          </geometry>
        </visual>
        <velocity_decay>
          <linear>0</linear>
          <angular>0</angular>
        </velocity_decay>
        <self_collide>0</self_collide>
        <kinematic>0</kinematic>
        <gravity>1</gravity>
      </link>
    </model>
    <model name='Road_cure_left2_0'>
      <static>1</static>
      <pose>23.5955 -27.4864 0 0 -0 0</pose>
      <link name='link'>
        <visual name='visual'>
          <pose>0.16 0 -0.05 0 -0 0</pose>
          <geometry>
            <mesh>
              <uri>model://Road_Curve_left2/Road_Curve_left2.dae</uri>
              <scale>0.995 0.995 0.995</scale>
            </mesh>
          </geometry>
        </visual>
        <velocity_decay>
          <linear>0</linear>
          <angular>0</angular>
        </velocity_decay>
        <self_collide>0</self_collide>
        <kinematic>0</kinematic>
        <gravity>1</gravity>
      </link>
    </model>
    <model name='road_3'>
      <static>1</static>
      <pose>24 -11 0 0 -0 0</pose>
      <link name='link'>
        <visual name='visual'>
          <pose>0 0 0.005 0 -0 0</pose>
          <geometry>
            <mesh>
              <uri>model://road/road.dae</uri>
            </mesh>
          </geometry>
        </visual>
        <velocity_decay>
          <linear>0</linear>
          <angular>0</angular>
        </velocity_decay>
        <self_collide>0</self_collide>
        <kinematic>0</kinematic>
        <gravity>1</gravity>
      </link>
    </model>
    <model name='cross_road'>
      <static>1</static>
      <pose>24.4241 2 0 0 -0 0</pose>
      <link name='link'>
        <visual name='visual'>
          <pose>0 0.2 -0.65 0 -0 0</pose>
          <geometry>
            <mesh>
              <uri>model://cross_road/cross_road.dae</uri>
            </mesh>
          </geometry>
        </visual>
        <velocity_decay>
          <linear>0</linear>
          <angular>0</angular>
        </velocity_decay>
        <self_collide>0</self_collide>
        <kinematic>0</kinematic>
        <gravity>1</gravity>
      </link>
    </model>
    <model name='road_4'>
      <static>1</static>
      <pose>43.5554 2 0 0 -0 0</pose>
      <link name='link'>
        <visual name='visual'>
          <pose>0 0 0.005 0 -0 0</pose>
          <geometry>
            <mesh>
              <uri>model://road/road.dae</uri>
            </mesh>
          </geometry>
        </visual>
        <velocity_decay>
          <linear>0</linear>
          <angular>0</angular>
        </velocity_decay>
        <self_collide>0</self_collide>
        <kinematic>0</kinematic>
        <gravity>1</gravity>
      </link>
    </model>
    <model name='road_5'>
      <static>1</static>
      <pose>53 2 0 0 -0 0</pose>
      <link name='link'>
        <visual name='visual'>
          <pose>0 0 0.005 0 -0 0</pose>
          <geometry>
            <mesh>
              <uri>model://road/road.dae</uri>
            </mesh>
          </geometry>
        </visual>
        <velocity_decay>
          <linear>0</linear>
          <angular>0</angular>
        </velocity_decay>
        <self_collide>0</self_collide>
        <kinematic>0</kinematic>
        <gravity>1</gravity>
      </link>
    </model>
    <model name='road_6'>
      <static>1</static>
      <pose>62.586 2 0 0 -0 0</pose>
      <link name='link'>
        <visual name='visual'>
          <pose>0 0 0.005 0 -0 0</pose>
          <geometry>
            <mesh>
              <uri>model://road/road.dae</uri>
            </mesh>
          </geometry>
        </visual>
        <velocity_decay>
          <linear>0</linear>
          <angular>0</angular>
        </velocity_decay>
        <self_collide>0</self_collide>
        <kinematic>0</kinematic>
        <gravity>1</gravity>
      </link>
    </model>
    <model name='Road_cure_left'>
      <static>1</static>
      <pose>80 9 0 0 -0 0</pose>
      <link name='link'>
        <visual name='visual'>
          <pose>-0.14 0 -0.1 0 -0 0</pose>
          <geometry>
            <mesh>
              <uri>model://Road_Curve_left/Road_Curve_left.dae</uri>
            </mesh>
          </geometry>
        </visual>
        <velocity_decay>
          <linear>0</linear>
          <angular>0</angular>
        </velocity_decay>
        <self_collide>0</self_collide>
        <kinematic>0</kinematic>
        <gravity>1</gravity>
      </link>
    </model>
    <model name='road_7'>
      <static>1</static>
      <pose>82 22 0 0 -0 0</pose>
      <link name='link'>
        <visual name='visual'>
          <pose>0 0 0.005 0 -0 0</pose>
          <geometry>
            <mesh>
              <uri>model://road/road.dae</uri>
            </mesh>
          </geometry>
        </visual>
        <velocity_decay>
          <linear>0</linear>
          <angular>0</angular>
        </velocity_decay>
        <self_collide>0</self_collide>
        <kinematic>0</kinematic>
        <gravity>1</gravity>
      </link>
    </model>
    <model name='road_8'>
      <static>1</static>
      <pose>82 32 0 0 -0 0</pose>
      <link name='link'>
        <visual name='visual'>
          <pose>0 0 0.005 0 -0 0</pose>
          <geometry>
            <mesh>
              <uri>model://road/road.dae</uri>
            </mesh>
          </geometry>
        </visual>
        <velocity_decay>
          <linear>0</linear>
          <angular>0</angular>
        </velocity_decay>
        <self_collide>0</self_collide>
        <kinematic>0</kinematic>
        <gravity>1</gravity>
      </link>
    </model>
    <model name='road_9'>
      <static>1</static>
      <pose>81.412 42 0 0 -0 0</pose>
      <link name='link'>
        <visual name='visual'>
          <pose>0 0 0.005 0 -0 0</pose>
          <geometry>
            <mesh>
              <uri>model://road/road.dae</uri>
            </mesh>
          </geometry>
        </visual>
        <velocity_decay>
          <linear>0</linear>
          <angular>0</angular>
        </velocity_decay>
        <self_collide>0</self_collide>
        <kinematic>0</kinematic>
        <gravity>1</gravity>
      </link>
    </model>
    <model name='road_10'>
      <static>1</static>
      <pose>81.5143 52 0 0 -0 0</pose>
      <link name='link'>
        <visual name='visual'>
          <pose>0 0 0.005 0 -0 0</pose>
          <geometry>
            <mesh>
              <uri>model://road/road.dae</uri>
            </mesh>
          </geometry>
        </visual>
        <velocity_decay>
          <linear>0</linear>
          <angular>0</angular>
        </velocity_decay>
        <self_collide>0</self_collide>
        <kinematic>0</kinematic>
        <gravity>1</gravity>
      </link>
    </model>
    <state world_name='vilma_task_1'>
      <sim_time>831 586000000</sim_time>
      <real_time>863 997943410</real_time>
      <wall_time>1384466213 396019451</wall_time>
      <model name='Road_cure_left'>
        <pose>79.5389 5.3144 0.035178 0 0 -1.57091</pose>
        <link name='link'>
          <pose>79.5389 5.3144 0.035178 0 0 -1.57091</pose>
          <velocity>0 0 0 0 -0 0</velocity>
          <acceleration>0 0 0 0 -0 0</acceleration>
          <wrench>0 0 0 0 -0 0</wrench>
        </link>
      </model>
      <model name='Road_cure_left2'>
        <pose>15.627 -27.5394 0 0 0 -3.11771</pose>
        <link name='link'>
          <pose>15.627 -27.5394 0 0 0 -3.11771</pose>
          <velocity>0 0 0 0 -0 0</velocity>
          <acceleration>0 0 0 0 -0 0</acceleration>
          <wrench>0 0 0 0 -0 0</wrench>
        </link>
      </model>
      <model name='Road_cure_left2_0'>
        <pose>24.5891 -26.5461 0 0 0 -1.54485</pose>
        <link name='link'>
          <pose>24.5891 -26.5461 0 0 0 -1.54485</pose>
          <velocity>0 0 0 0 -0 0</velocity>
          <acceleration>0 0 0 0 -0 0</acceleration>
          <wrench>0 0 0 0 -0 0</wrench>
        </link>
      </model>
      <model name='Road_cure_right2'>
        <pose>14.0733 -18.1413 0 0 0 -1.57694</pose>
        <link name='link'>
          <pose>14.0733 -18.1413 0 0 0 -1.57694</pose>
          <velocity>0 0 0 0 -0 0</velocity>
          <acceleration>0 0 0 0 -0 0</acceleration>
          <wrench>0 0 0 0 -0 0</wrench>
        </link>
      </model>
      <model name='cross_road'>
        <pose>24.3897 1.99921 0 0 -0 0</pose>
        <link name='link'>
          <pose>24.3897 1.99921 0 0 -0 0</pose>
          <velocity>0 0 0 0 -0 0</velocity>
          <acceleration>0 0 0 0 -0 0</acceleration>
          <wrench>0 0 0 0 -0 0</wrench>
        </link>
      </model>
      <model name='grass_plane'>
        <pose>0 0 0 0 -0 0</pose>
        <link name='link'>
          <pose>0 0 0 0 -0 0</pose>
          <velocity>0 0 0 0 -0 0</velocity>
          <acceleration>0 0 0 0 -0 0</acceleration>
          <wrench>0 0 0 0 -0 0</wrench>
        </link>
      </model>
      <model name='road'>
        <pose>-24 -18 0 0 -0 0</pose>
        <link name='link'>
          <pose>-24 -18 0 0 -0 0</pose>
          <velocity>0 0 0 0 -0 0</velocity>
          <acceleration>0 0 0 0 -0 0</acceleration>
          <wrench>0 0 0 0 -0 0</wrench>
        </link>
      </model>
      <model name='road_0'>
        <pose>-14.4828 -18 0 0 -0 0</pose>
        <link name='link'>
          <pose>-14.4828 -18 0 0 -0 0</pose>
          <velocity>0 0 0 0 -0 0</velocity>
          <acceleration>0 0 0 0 -0 0</acceleration>
          <wrench>0 0 0 0 -0 0</wrench>
        </link>
      </model>
      <model name='road_1'>
        <pose>-5 -18 0 0 -0 0</pose>
        <link name='link'>
          <pose>-5 -18 0 0 -0 0</pose>
          <velocity>0 0 0 0 -0 0</velocity>
          <acceleration>0 0 0 0 -0 0</acceleration>
          <wrench>0 0 0 0 -0 0</wrench>
        </link>
      </model>
      <model name='road_10'>
        <pose>82.2424 50.6695 0 0 -0 1.58404</pose>
        <link name='link'>
          <pose>82.2424 50.6695 0 0 -0 1.58404</pose>
          <velocity>0 0 0 0 -0 0</velocity>
          <acceleration>0 0 0 0 -0 0</acceleration>
          <wrench>0 0 0 0 -0 0</wrench>
        </link>
      </model>
      <model name='road_2'>
        <pose>4.49281 -18 0 0 -0 0</pose>
        <link name='link'>
          <pose>4.49281 -18 0 0 -0 0</pose>
          <velocity>0 0 0 0 -0 0</velocity>
          <acceleration>0 0 0 0 -0 0</acceleration>
          <wrench>0 0 0 0 -0 0</wrench>
        </link>
      </model>
      <model name='road_3'>
        <pose>24.2833 -17.0932 0 0 0 -1.54199</pose>
        <link name='link'>
          <pose>24.2833 -17.0932 0 0 0 -1.54199</pose>
          <velocity>0 0 0 0 -0 0</velocity>
          <acceleration>0 0 0 0 -0 0</acceleration>
          <wrench>0 0 0 0 -0 0</wrench>
        </link>
      </model>
      <model name='road_4'>
        <pose>43.5554 2 0 0 -0 0</pose>
        <link name='link'>
          <pose>43.5554 2 0 0 -0 0</pose>
          <velocity>0 0 0 0 -0 0</velocity>
          <acceleration>0 0 0 0 -0 0</acceleration>
          <wrench>0 0 0 0 -0 0</wrench>
        </link>
      </model>
      <model name='road_5'>
        <pose>53 2 0 0 -0 0</pose>
        <link name='link'>
          <pose>53 2 0 0 -0 0</pose>
          <velocity>0 0 0 0 -0 0</velocity>
          <acceleration>0 0 0 0 -0 0</acceleration>
          <wrench>0 0 0 0 -0 0</wrench>
        </link>
      </model>
      <model name='road_6'>
        <pose>62.586 2 0 0 -0 0</pose>
        <link name='link'>
          <pose>62.586 2 0 0 -0 0</pose>
          <velocity>0 0 0 0 -0 0</velocity>
          <acceleration>0 0 0 0 -0 0</acceleration>
          <wrench>0 0 0 0 -0 0</wrench>
        </link>
      </model>
      <model name='road_7'>
        <pose>82.6769 22.0067 0 0 0 -1.56087</pose>
        <link name='link'>
          <pose>82.6769 22.0067 0 0 0 -1.56087</pose>
          <velocity>0 0 0 0 -0 0</velocity>
          <acceleration>0 0 0 0 -0 0</acceleration>
          <wrench>0 0 0 0 -0 0</wrench>
        </link>
      </model>
      <model name='road_8'>
        <pose>82.4757 31.8533 0 0 0 -1.54422</pose>
        <link name='link'>
          <pose>82.4757 31.8533 0 0 0 -1.54422</pose>
          <velocity>0 0 0 0 -0 0</velocity>
          <acceleration>0 0 0 0 -0 0</acceleration>
          <wrench>0 0 0 0 -0 0</wrench>
        </link>
      </model>
      <model name='road_9'>
        <pose>82.2426 41.7031 0 0 0 -1.55212</pose>
        <link name='link'>
          <pose>82.2426 41.7031 0 0 0 -1.55212</pose>
          <velocity>0 0 0 0 -0 0</velocity>
          <acceleration>0 0 0 0 -0 0</acceleration>
          <wrench>0 0 0 0 -0 0</wrench>
        </link>
      </model>
      <model name='vilma_vehicle'>
        <pose>-18.4161 -19.9782 0.060802 -6.3e-05 7.5e-05 0.01286</pose>
        <link name='camera_front'>
          <pose>-16.9161 -19.9589 1.06069 -6.3e-05 7.5e-05 0.01286</pose>
          <velocity>0.001172 0.000164 -0.012206 -0.000342 -0.000386 4.8e-05</velocity>
          <acceleration>0 0 0 0 -0 0</acceleration>
          <wrench>0 0 0 0 -0 0</wrench>
        </link>
        <link name='vilma_draw::FNR_switch'>
          <pose>-17.8557 -19.9909 2.06076 -6.4e-05 0.151162 0.01285</pose>
          <velocity>0.000789 0.000422 -0.012557 -0.000348 0.000103 9e-05</velocity>
          <acceleration>0 0 0 0 -0 0</acceleration>
          <wrench>0 0 0 0 -0 0</wrench>
        </link>
        <link name='vilma_draw::brake_pedal'>
          <pose>-17.7795 -19.6999 2.06073 -6.3e-05 7.5e-05 0.01286</pose>
          <velocity>0.001526 0.000435 -0.013082 -0.000278 -0.000427 8.2e-05</velocity>
          <acceleration>0 0 0 0 -0 0</acceleration>
          <wrench>0 0 0 0 -0 0</wrench>
        </link>
        <link name='vilma_draw::chassis'>
          <pose>-18.4161 -19.9782 0.060802 -6.3e-05 7.5e-05 0.01286</pose>
          <velocity>0.001537 -0.000317 -0.012808 -0.000347 -0.000362 9e-05</velocity>
          <acceleration>0 0 0 0 -0 0</acceleration>
          <wrench>0 0 0 0 -0 0</wrench>
        </link>
        <link name='vilma_draw::front_left_wheel'>
          <pose>-17.1751 -19.2272 0.380832 -1.46808 1.05926 0.101819</pose>
          <velocity>0.001251 -0.000585 -0.032769 0.005913 0.002952 -0.001309</velocity>
          <acceleration>0 0 0 0 -0 0</acceleration>
          <wrench>0 0 0 0 -0 0</wrench>
        </link>
        <link name='vilma_draw::front_left_wheel_steering_block'>
          <pose>-17.1738 -19.3272 0.380918 1.57074 7.5e-05 0.01289</pose>
          <velocity>0.001386 -0.000676 -0.042328 -0.001142 -0.000315 0.000822</velocity>
          <acceleration>0 0 0 0 -0 0</acceleration>
          <wrench>0 0 0 0 -0 0</wrench>
        </link>
        <link name='vilma_draw::front_right_wheel'>
          <pose>-17.1562 -20.697 0.380872 1.45761 1.10897 -0.087856</pose>
          <velocity>0.001277 0.000296 -0.025024 -0.004088 0.003159 0.000279</velocity>
          <acceleration>0 0 0 0 -0 0</acceleration>
          <wrench>0 0 0 0 -0 0</wrench>
        </link>
        <link name='vilma_draw::front_right_wheel_steering_block'>
          <pose>-17.158 -20.5971 0.380922 1.57073 7.5e-05 0.012813</pose>
          <velocity>0.001435 0.000383 -0.031228 0.000204 -0.000285 -0.001134</velocity>
          <acceleration>0 0 0 0 -0 0</acceleration>
          <wrench>0 0 0 0 -0 0</wrench>
        </link>
        <link name='vilma_draw::gas_pedal'>
          <pose>-17.7873 -19.87 2.06072 -6.3e-05 7.5e-05 0.01286</pose>
          <velocity>-0.007367 0.000317 -0.00441 -0.000311 -0.000352 8e-05</velocity>
          <acceleration>0 0 0 0 -0 0</acceleration>
          <wrench>0 0 0 0 -0 0</wrench>
        </link>
        <link name='vilma_draw::hand_brake'>
          <pose>-17.9161 -19.9717 1.11077 -3.14152 0.535513 -3.1287</pose>
          <velocity>0.001154 9.2e-05 -0.012587 -0.000346 8e-06 8.9e-05</velocity>
          <acceleration>0 0 0 0 -0 0</acceleration>
          <wrench>0 0 0 0 -0 0</wrench>
        </link>
        <link name='vilma_draw::rear_left_wheel'>
          <pose>-19.6759 -19.2593 0.380849 1.24354 1.41542 2.83003</pose>
          <velocity>0.001302 -0.00018 -0.013474 0.002223 0.00333 -9.9e-05</velocity>
          <acceleration>0 0 0 0 -0 0</acceleration>
          <wrench>0 0 0 0 -0 0</wrench>
        </link>
        <link name='vilma_draw::rear_right_wheel'>
          <pose>-19.657 -20.7292 0.380927 1.51018 0.580437 -0.019952</pose>
          <velocity>0.001795 -0.000388 -0.013146 3.09056 -0.635471 2.95297</velocity>
          <acceleration>0 0 0 0 -0 0</acceleration>
          <wrench>0 0 0 0 -0 0</wrench>
        </link>
        <link name='vilma_draw::steering_wheel'>
          <pose>-18.0798 -19.6737 2.06076 -0.000114 -0.869925 0.012955</pose>
          <velocity>0.00076 0.0004 -0.012752 0.000296 -0.000378 -0.000449</velocity>
          <acceleration>0 0 0 0 -0 0</acceleration>
          <wrench>0 0 0 0 -0 0</wrench>
        </link>
      </model>
    </state>
  </world>
</sdf>
